<?xml version="1.0"?>
<!-- Revolute-Revolute Manipulator -->
<robot xmlns:xacro="http://www.ros.org/wiki/xacro" >
  <!--Constant for the robotv1-->
  <xacro:property name="joint_friction" value="0.015"/>
  <xacro:property name="joint_damping" value="0.03"/>
  <xacro:property name="joint_effort" value="10.0"/>
  <xacro:property name="joint_vel" value="6.0"/>


  <xacro:property name="lx_u0" value="0.04"/>
  <xacro:property name="ly_u0" value="0.03"/>
  <xacro:property name="lz_u0" value="0.06"/>

  <xacro:property name="lx_u1" value="0.06"/>
  <xacro:property name="ly_u1" value="0.03"/>
  <xacro:property name="lz_u1" value="0.09"/>

  <xacro:property name="lx_u2" value="0.03"/>
  <xacro:property name="ly_u2" value="0.04"/>
  <xacro:property name="lz_u2" value="0.06"/>

  <xacro:property name="lx_l0" value="0.015"/>
  <xacro:property name="ly_l0" value="0.015"/>
  <xacro:property name="lz_l0" value="0.16"/>
  
  <xacro:property name="lx_l1" value="0.04"/>
  <xacro:property name="ly_l1" value="0.03"/>
  <xacro:property name="lz_l1" value="0.06"/>

  <xacro:property name="lx_l2" value="0.03"/>
  <xacro:property name="ly_l2" value="0.04"/>
  <xacro:property name="lz_l2" value="0.06"/>

  <xacro:property name="lx_l3" value="0.1"/>
  <xacro:property name="ly_l3" value="0.04"/>
  <xacro:property name="lz_l3" value="0.008"/>
  
  <xacro:property name="lx_l4" value="0.1"/>
  <xacro:property name="ly_l4" value="0.04"/>
  <xacro:property name="lz_l4" value="0.005"/>
  
  <xacro:property name="lx_imu_link" value="0.03"/>
  <xacro:property name="ly_imu_link" value="0.03"/>
  <xacro:property name="lz_imu_link" value="0.005"/>

  <xacro:include filename="$(find robotv1_description)/urdf/leg.gazebo" />
  <xacro:include filename="$(find robotv1_description)/urdf/utilities.xacro"/>

  <xacro:macro name="leg" params="prefix reflect" >
    <joint name="${prefix}_H0" type="revolute" >
      <parent link="pelvis"/>
      <child link="${prefix}_u0"/>
      <origin xyz="0 ${ly_pelvis*reflect/2} 0"/>
      <axis xyz="0 1 0"/>
      <dynamics damping="${joint_damping}" friction="${joint_friction}"/>
      <limit effort="${joint_effort}" velocity="${joint_vel}" lower="${-pi/2}" upper="${pi/2}" />
      <!--
      <safety_controller k_velocity="10" k_position="15" soft_lower_limit="${-7*pi/8}" soft_upper_limit="${7*pi/8}" />
       -->
    </joint>
    
    <transmission name="${prefix}_H0_tran">
      <type>transmission_interface/SimpleTransmission</type>
      <joint name="${prefix}_H0">
        <hardwareInterface>hardware_interface/EffortJointInterface</hardwareInterface>
      </joint>
      <actuator name="${prefix}_H0_motor">
        <hardwareInterface>hardware_interface/EffortJointInterface</hardwareInterface>
        <mechanicalReduction>1</mechanicalReduction>
      </actuator>
    </transmission>

    
    <link name="${prefix}_u0" >
      <visual>
        <origin xyz="0 ${ly_u0*reflect/2} 0" rpy="0 0 0"/>
        <geometry>
          <box size="${lx_u0} ${ly_u0} ${lz_u0}"/>
        </geometry>
        <material name="black"/>
      </visual>
      <inertial>
        <origin xyz="0 ${ly_u0*reflect/2} 0" rpy="0 0 0"/>
        <xacro:box_inertia  lenx="${lx_u0}" leny="${ly_u0}" lenz="${lz_u0}" />
      </inertial>
      <collision>
        <origin xyz="0 ${ly_u0*reflect/2} 0" rpy="0 0 0"/>
        <geometry>
          <box size="${lx_u0} ${ly_u0} ${lz_u0}"/>
        </geometry>
      </collision>
    </link>
  
    <joint name="${prefix}_H1" type="revolute" >
       <parent link="${prefix}_u0"/>
       <child link="${prefix}_u1"/>
       <origin xyz= "0 ${ly_u0*reflect} 0"/>
       <axis xyz="1 0 0"/>
       <dynamics damping="${joint_damping}" friction="${joint_friction}"/>
       <limit effort="${joint_effort}" velocity="${joint_vel}" lower="${-pi/2}" upper="${pi/2}" />
    </joint>
    <transmission name="${prefix}_H1_tran">
      <type>transmission_interface/SimpleTransmission</type>
      <joint name="${prefix}_H1">
        <hardwareInterface>hardware_interface/EffortJointInterface</hardwareInterface>
      </joint>
      <actuator name="${prefix}_H1_motor">
        <hardwareInterface>hardware_interface/EffortJointInterface</hardwareInterface>
        <mechanicalReduction>1</mechanicalReduction>
      </actuator>
    </transmission>

    <link name="${prefix}_u1" >
      <visual>
        <origin xyz="0 0 ${-lz_u1/2 }" rpy="0 0 0"/>
        <geometry>
          <box size="${lx_u1} ${ly_u1} ${lz_u1}"/>
        </geometry>
        <material name="orange"/>
      </visual>
      <inertial>
        <origin xyz="0 0 ${-lz_u1/2 }" rpy="0 0 0"/>
        <xacro:box_inertia  lenx="${lx_u1}" leny="${ly_u1}" lenz="${lz_u1}" />
      </inertial>
      <collision>
        <origin xyz="0 0 ${-1*lz_u1/2 }" rpy="0 0 0"/>
        <geometry>
          <box size="${lx_u1} ${ly_u1} ${lz_u1}"/>
        </geometry>
      </collision>
    </link>
    
    <joint name="${prefix}_H2" type="revolute" >
      <parent link="${prefix}_u1"/>
      <child link="${prefix}_u2"/>
      <origin xyz="0 0 ${-lz_u1}"/>
      <axis xyz="0 0 1"/>
      <dynamics damping="${joint_damping}" friction="${joint_friction}"/>
      <limit effort="${joint_effort}" velocity="${joint_vel}" lower="${-pi/2}" upper="${pi/2}" />
    </joint>
    
    <transmission name="${prefix}_H2_tran">
      <type>transmission_interface/SimpleTransmission</type>
      <joint name="${prefix}_H2">
        <hardwareInterface>hardware_interface/EffortJointInterface</hardwareInterface>
      </joint>
      <actuator name="${prefix}_H2_motor">
        <hardwareInterface>hardware_interface/EffortJointInterface</hardwareInterface>
        <mechanicalReduction>1</mechanicalReduction>
      </actuator>
    </transmission>

    <link name="${prefix}_u2" >
      <visual>
        <origin xyz="0 0 ${-lz_u2/2}" rpy="0 0 0"/>
        <geometry>
          <box size="${lx_u2} ${ly_u2} ${lz_u2}"/>
        </geometry>
        <material name="black"/>
      </visual>
      <inertial>
        <origin xyz="0 0 ${-lz_u2/2}" rpy="0 0 0"/>
        <xacro:box_inertia  lenx="${lx_u2}" leny="${ly_u2}" lenz="${lz_u2}" />
      </inertial>
      <collision>
        <origin xyz="0 0 ${-lz_u2/2}" rpy="0 0 0"/>
        <geometry>
          <box size="${lx_u2} ${ly_u2} ${lz_u2}"/>
        </geometry>
      </collision>
    </link>

    <joint name="${prefix}_K0" type="revolute" >
      <parent link="${prefix}_u2"/>
      <child link="${prefix}_l0"/>
      <origin xyz="0 0 ${-lz_u2}"/>
      <axis xyz="0 1 0"/>
      <dynamics damping="${joint_damping}" friction="${joint_friction}"/>
      <limit effort="${joint_effort}" velocity="${joint_vel}" lower="0" upper="${7*pi/8}" />
    </joint>
    
    <transmission name="${prefix}_K0_tran">
      <type>transmission_interface/SimpleTransmission</type>
      <joint name="${prefix}_K0">
        <hardwareInterface>hardware_interface/EffortJointInterface</hardwareInterface>
      </joint>
      <actuator name="${prefix}_K0_motor">
        <hardwareInterface>hardware_interface/EffortJointInterface</hardwareInterface>
        <mechanicalReduction>1</mechanicalReduction>
      </actuator>
    </transmission>

    <link name="${prefix}_l0" >
      <visual>
        <origin xyz="0 0 ${-lz_l0/2}" rpy="0 0 0"/>
        <geometry>
          <box size="${lx_l0} ${ly_l0} ${lz_l0}"/>
        </geometry>
        <material name="orange"/>
      </visual>
      <inertial>
        <origin xyz="0 0 ${-lz_l0/2}" rpy="0 0 0"/>
        <xacro:box_inertia  lenx="${lx_l0}" leny="${ly_l0}" lenz="${lz_l0}" />
      </inertial>
      <collision>
       <origin xyz="0 0 ${-lz_l0/2}" rpy="0 0 0"/>
       <geometry>
         <box size="${lx_l0} ${ly_l0} ${lz_l0}"/>
       </geometry>
      </collision>
    </link>

    <joint name="${prefix}_A0" type="revolute" >
      <parent link="${prefix}_l0"/>
      <child link="${prefix}_l1"/>
      <origin xyz="0 0 ${-lz_l0+lz_l1/2}" rpy="0 0 0"/>
      <axis xyz="1 0 0"/>
      <dynamics damping="${joint_damping}" friction="${joint_friction}"/>
      <limit effort="${joint_effort}" velocity="${joint_vel}" lower="${-pi/4}" upper="${pi/4}" />
    </joint>
    
    <transmission name="${prefix}_A0_tran">
      <type>transmission_interface/SimpleTransmission</type>
      <joint name="${prefix}_A0">
        <hardwareInterface>hardware_interface/EffortJointInterface</hardwareInterface>
      </joint>
      <actuator name="${prefix}_A0_motor">
        <hardwareInterface>hardware_interface/EffortJointInterface</hardwareInterface>
        <mechanicalReduction>1</mechanicalReduction>
      </actuator>
    </transmission>

    <link name="${prefix}_l1" >
      <visual>
      <origin xyz="0 0 0" rpy="0 0 0"/>
        <geometry>
          <box size="${lx_l1} ${ly_l1} ${lz_l1}"/>
        </geometry>
        <material name="black"/>
      </visual>
      <inertial>
        <origin xyz="0 0 0" rpy="0 0 0"/>
        <xacro:box_inertia  lenx="${lx_l1}" leny="${ly_l1}" lenz="${lz_l1}" />
      </inertial>
      <collision>
        <origin xyz="0 0 0" rpy="0 0 0"/>
        <geometry>
          <box size="${lx_l1} ${ly_l1} ${lz_l1}"/>
        </geometry>
      </collision>
    </link>

    <joint name="${prefix}_A1" type="revolute" >
      <parent link="${prefix}_l1"/>
      <child link="${prefix}_l2"/>
      <origin xyz="${-lx_l1/2} 0 0"/>
      <axis xyz="0 1 0"/>
      <dynamics damping="${joint_damping}" friction="${joint_friction}"/>
      <limit effort="${joint_effort}" velocity="${joint_vel}" lower="${-pi/4}" upper="${pi/4}" />
    </joint>
    
    <transmission name="${prefix}_A1_tran">
      <type>transmission_interface/SimpleTransmission</type>
      <joint name="${prefix}_A1">
        <hardwareInterface>hardware_interface/EffortJointInterface</hardwareInterface>
      </joint>
      <actuator name="${prefix}_A1_motor">
        <hardwareInterface>hardware_interface/EffortJointInterface</hardwareInterface>
        <mechanicalReduction>1</mechanicalReduction>
      </actuator>
    </transmission>

    <link name="${prefix}_l2" >
      <visual>
        <origin xyz="0 0 ${-lz_l2/2}" rpy="0 0 0"/>
        <geometry>
          <box size="${lx_l2} ${ly_l2} ${lz_l2}"/>
        </geometry>
        <material name="orange"/>
      </visual>
      <inertial>
        <origin xyz="0 0 ${-lz_l2/2}" rpy="0 0 0"/>
        <xacro:box_inertia  lenx="${lx_l2}" leny="${ly_l2}" lenz="${lz_l2}" />
      </inertial>
      <collision>
        <origin xyz="0 0 ${-lz_l2/2}" rpy="0 0 0"/>
        <geometry>
          <box size="${lx_l2} ${ly_l2} ${lz_l2}"/>
        </geometry>
      </collision>
    </link>

    <joint name="${prefix}_l3_fix" type="fixed" >
      <parent link="${prefix}_l2"/>
      <child link="${prefix}_l3"/>
      <origin xyz="0 0 ${-lz_l2}"/>
    </joint>

    <link name="${prefix}_l3" >
      <visual>
        <origin xyz="${lx_l3/2-lx_l2/2} 0 ${-lz_l3/2}" rpy="0 0 0"/>
        <geometry>
          <box size="${lx_l3} ${ly_l3} ${lz_l3}"/>
        </geometry>
        <material name="orange"/>
      </visual>
      <inertial>
        <origin xyz="${lx_l3/2-lx_l2/2} 0 ${-lz_l3/2}" rpy="0 0 0"/>
        <xacro:box_inertia  lenx="${lx_l3}" leny="${ly_l3}" lenz="${lz_l3}" />
      </inertial>
      <collision>
        <origin xyz="${lx_l3/2-lx_l2/2} 0 ${-lz_l3/2}" rpy="0 0 0"/>
        <geometry>
           <box size="${lx_l3} ${ly_l3} ${lz_l3}"/>
        </geometry>
      </collision>
    </link>


    <joint name="${prefix}_ft_sensor" type="revolute" >
      <parent link="${prefix}_l3"/>
      <child link="${prefix}_l4"/>
      <origin xyz="${lx_l4/2-lx_l2/2} 0 ${-lz_l3}"/>
      <limit effort="10.0" velocity="1.0" upper="0.0" lower="0.0"/>
    </joint>
    <transmission name="${prefix}_ft_sensor_tran">
      <type>transmission_interface/SimpleTransmission</type>
      <joint name="${prefix}_ft_sensor">
        <hardwareInterface>hardware_interface/EffortJointInterface</hardwareInterface>
      </joint>
      <actuator name="${prefix}_ft_sensor_motor">
        <hardwareInterface>hardware_interface/EffortJointInterface</hardwareInterface>
        <mechanicalReduction>1</mechanicalReduction>
      </actuator>
    </transmission>

    <link name="${prefix}_l4" >
      <visual>
        <origin xyz="0 0 ${-lz_l4/2}" rpy="0 0 0"/>
        <geometry>
          <box size="${lx_l4} ${ly_l4} ${lz_l4}"/>
        </geometry>
        <material name="black"/>
      </visual>
      <inertial>
        <origin xyz="0 0 ${-lz_l4/2}" rpy="0 0 0"/>
        <xacro:box_inertia  lenx="${lx_l4}" leny="${ly_l4}" lenz="${lz_l4}" />
      </inertial>
      <collision>
        <origin xyz="0 0 ${-lz_l4/2}" rpy="0 0 0"/>
        <geometry>
           <box size="${lx_l4} ${ly_l4} ${lz_l4}"/>
        </geometry>
      </collision>
    </link>

    <joint name="${prefix}_l3_to_imu_link" type="fixed">
      <origin xyz="${lx_l3/2} 0 0" rpy="0 0 0" />
      <parent link="${prefix}_l3"/>
      <child link="${prefix}_imu_link"/>
    </joint>

    <link name="${prefix}_imu_link" >
      <visual>
        <origin xyz="0 0 ${lz_imu_link/2.0}" rpy="0 0 0" /> 
        <geometry>
          <box size="${lx_imu_link} ${ly_imu_link} ${lz_imu_link}"/>
        </geometry>
        <material name="blue"/>
      </visual>
      <inertial>
        <origin xyz="0 0 ${lz_imu_link/2.0}" rpy="0 0 0" /> 
        <xacro:box_inertia lenx="${lx_imu_link}" leny="${ly_imu_link}" lenz="${lz_imu_link}"/>
      </inertial>
      <collision>
        <origin xyz="0 0 0" rpy="0 0 0" /> 
        <geometry>
          <box size="${lx_imu_link} ${ly_imu_link} ${lz_imu_link}"/>
        </geometry>
      </collision>
    </link>
 

   <xacro:leg_gazebo_reference prefix="${prefix}"/>
 </xacro:macro>

</robot>
