<?xml version="1.0" ?>
<!-- =================================================================================== -->
<!-- |    This document was autogenerated by xacro from robotv1.xacro                  | -->
<!-- |    EDITING THIS FILE BY HAND IS NOT RECOMMENDED                                 | -->
<!-- =================================================================================== -->
<!-- Revolute-Revolute Manipulator -->
<robot name="robotv1" xmlns:xacro="http://www.ros.org/wiki/xacro">
  <material name="black">
    <color rgba="0.0 0.0 0.0 1.0"/>
  </material>
  <material name="blue">
    <color rgba="0.0 0.0 0.8 1.0"/>
  </material>
  <material name="green">
    <color rgba="0.0 0.8 0.0 1.0"/>
  </material>
  <material name="grey">
    <color rgba="0.2 0.2 0.2 1.0"/>
  </material>
  <material name="orange">
    <color rgba="1.0 0.423529411765 0.0392156862745 1.0"/>
  </material>
  <material name="brown">
    <color rgba="0.870588235294 0.811764705882 0.764705882353 1.0"/>
  </material>
  <material name="red">
    <color rgba="0.8 0.0 0.0 1.0"/>
  </material>
  <material name="white">
    <color rgba="1.0 1.0 1.0 1.0"/>
  </material>
  <!-- ros_control plugin -->
  <gazebo>
    <plugin filename="libgazebo_ros_control.so" name="gazebo_ros_control">
      <robotNamespace>/robotv1</robotNamespace>
      <robotSimType>gazebo_ros_control/DefaultRobotHWSim</robotSimType>
      <legacyModeNS>true</legacyModeNS>
    </plugin>
  </gazebo>
  <gazebo reference="base">
    <mu1>0.2</mu1>
    <mu2>0.2</mu2>
    <material>Gazebo/Orange</material>
  </gazebo>
  <!-- Link1 -->
  <gazebo reference="leftleg_hip_2">
    <material>Gazebo/Black</material>
  </gazebo>
  <gazebo reference="leftleg_hip_3">
    <mu1>0.2</mu1>
    <mu2>0.2</mu2>
    <material>Gazebo/Orange</material>
  </gazebo>
  <gazebo reference="leftleg_upp">
    <mu1>0.2</mu1>
    <mu2>0.2</mu2>
    <material>Gazebo/Black</material>
  </gazebo>
  <gazebo reference="leftleg_low">
    <mu1>0.2</mu1>
    <mu2>0.2</mu2>
    <material>Gazebo/Orange</material>
  </gazebo>
  <gazebo reference="leftleg_ang_1">
    <mu1>0.2</mu1>
    <mu2>0.2</mu2>
    <material>Gazebo/Black</material>
  </gazebo>
  <gazebo reference="leftleg_ang_2">
    <mu1>0.2</mu1>
    <mu2>0.2</mu2>
    <material>Gazebo/Orange</material>
  </gazebo>
  <gazebo reference="leftleg_foot">
    <mu1>0.2</mu1>
    <mu2>0.2</mu2>
    <material>Gazebo/Orange</material>
  </gazebo>
  <!-- Link1 -->
  <gazebo reference="rightleg_hip_2">
    <material>Gazebo/Black</material>
  </gazebo>
  <gazebo reference="rightleg_hip_3">
    <mu1>0.2</mu1>
    <mu2>0.2</mu2>
    <material>Gazebo/Orange</material>
  </gazebo>
  <gazebo reference="rightleg_upp">
    <mu1>0.2</mu1>
    <mu2>0.2</mu2>
    <material>Gazebo/Black</material>
  </gazebo>
  <gazebo reference="rightleg_low">
    <mu1>0.2</mu1>
    <mu2>0.2</mu2>
    <material>Gazebo/Orange</material>
  </gazebo>
  <gazebo reference="rightleg_ang_1">
    <mu1>0.2</mu1>
    <mu2>0.2</mu2>
    <material>Gazebo/Black</material>
  </gazebo>
  <gazebo reference="rightleg_ang_2">
    <mu1>0.2</mu1>
    <mu2>0.2</mu2>
    <material>Gazebo/Orange</material>
  </gazebo>
  <gazebo reference="rightleg_foot">
    <mu1>0.2</mu1>
    <mu2>0.2</mu2>
    <material>Gazebo/Orange</material>
  </gazebo>
  <link name="dummy"/>
  <joint name="dummy_to_base" type="fixed">
    <parent link="dummy"/>
    <child link="base"/>
  </joint>
  <link name="base">
    <visual>
      <origin rpy="0 0 0" xyz="0 0 0 "/>
      <geometry>
        <box size="0.04 0.06 0.03"/>
      </geometry>
      <material name="orange"/>
    </visual>
    <inertial>
      <mass value="0.56664"/>
      <inertia ixx="0.00021249" ixy="0.0" ixz="0.0" iyy="0.00021249" iyz="0.0" izz="0.00021249"/>
    </inertial>
    <collision>
      <origin rpy="0 0 0" xyz="0 0 0 "/>
      <geometry>
        <box size="0.04 0.06 0.03"/>
      </geometry>
    </collision>
  </link>
  <joint name="leftleg_hip_1_joint" type="revolute">
    <parent link="base"/>
    <child link="leftleg_hip_2"/>
    <origin xyz="0 0.03 0"/>
    <axis xyz="0 1 0"/>
    <dynamics damping="0.7"/>
    <limit effort="20" lower="-1.57079632679" upper="1.57079632679" velocity="1.0"/>
  </joint>
  <link name="leftleg_hip_2">
    <visual>
      <origin rpy="0 0 0" xyz="0 0.015 0"/>
      <geometry>
        <box size="0.04 0.03 0.05"/>
      </geometry>
      <material name="black"/>
    </visual>
    <inertial>
      <mass value="0.4722"/>
      <inertia ixx="0.00013379" ixy="0.0" ixz="0.0" iyy="0.00013379" iyz="0.0" izz="0.00013379"/>
    </inertial>
    <collision>
      <origin rpy="0 0 0" xyz="0 0.015 0"/>
      <geometry>
        <box size="0.04 0.03 0.05"/>
      </geometry>
    </collision>
  </link>
  <joint name="leftleg_hip_2_joint" type="revolute">
    <parent link="leftleg_hip_2"/>
    <child link="leftleg_hip_3"/>
    <origin xyz="0 0.03 0"/>
    <axis xyz="1 0 0"/>
    <dynamics damping="0.7"/>
    <limit effort="20" lower="-1.57079632679" upper="1.57079632679" velocity="1.0"/>
  </joint>
  <link name="leftleg_hip_3">
    <visual>
      <origin rpy="0 0 0" xyz="0 0 -0.015"/>
      <geometry>
        <box size="0.05 0.025 0.08"/>
      </geometry>
      <material name="orange"/>
    </visual>
    <inertial>
      <mass value="0.787"/>
      <inertia ixx="0.000460722916667" ixy="0.0" ixz="0.0" iyy="0.000460722916667" iyz="0.0" izz="0.000460722916667"/>
    </inertial>
    <collision>
      <origin rpy="0 0 0" xyz="0 0 -0.015"/>
      <geometry>
        <box size="0.05 0.025 0.08"/>
      </geometry>
    </collision>
  </link>
  <joint name="leftleg_hip_3_joint" type="revolute">
    <parent link="leftleg_hip_3"/>
    <child link="leftleg_upp"/>
    <origin xyz="0 0 -0.055"/>
    <axis xyz="0 0 1"/>
    <dynamics damping="0.7"/>
    <limit effort="20" lower="-1.57079632679" upper="1.57079632679" velocity="1.0"/>
  </joint>
  <link name="leftleg_upp">
    <visual>
      <origin rpy="0 0 0" xyz="0 0 -0.03"/>
      <geometry>
        <box size="0.025 0.05 0.06"/>
      </geometry>
      <material name="black"/>
    </visual>
    <inertial>
      <mass value="0.59025"/>
      <inertia ixx="0.00030004375" ixy="0.0" ixz="0.0" iyy="0.00030004375" iyz="0.0" izz="0.00030004375"/>
    </inertial>
    <collision>
      <origin rpy="0 0 0" xyz="0 0 -0.03"/>
      <geometry>
        <box size="0.025 0.05 0.06"/>
      </geometry>
    </collision>
  </link>
  <joint name="leftleg_knee_joint" type="revolute">
    <parent link="leftleg_upp"/>
    <child link="leftleg_low"/>
    <origin xyz="0 0 -0.06"/>
    <axis xyz="0 1 0"/>
    <dynamics damping="0.7"/>
    <limit effort="20" lower="0" upper="2.74889357189" velocity="1.0"/>
  </joint>
  <link name="leftleg_low">
    <visual>
      <origin rpy="0 0 0" xyz="0 0 -0.055"/>
      <geometry>
        <box size="0.01 0.01 0.11"/>
      </geometry>
      <material name="orange"/>
    </visual>
    <inertial>
      <mass value="0.08657"/>
      <inertia ixx="8.80128333333e-05" ixy="0.0" ixz="0.0" iyy="8.80128333333e-05" iyz="0.0" izz="8.80128333333e-05"/>
    </inertial>
    <collision>
      <origin rpy="0 0 0" xyz="0 0 -0.055"/>
      <geometry>
        <box size="0.01 0.01 0.11"/>
      </geometry>
    </collision>
  </link>
  <joint name="leftleg_ang_1_joint" type="revolute">
    <parent link="leftleg_low"/>
    <child link="leftleg_ang_1"/>
    <origin rpy="0 0 0" xyz="0 0 -0.085"/>
    <axis xyz="1 0 0"/>
    <dynamics damping="0.7"/>
    <limit effort="20" lower="-0.785398163397" upper="0.785398163397" velocity="1.0"/>
  </joint>
  <link name="leftleg_ang_1">
    <visual>
      <origin rpy="0 0 0" xyz="0 0 0"/>
      <geometry>
        <box size="0.04 0.02 0.05"/>
      </geometry>
      <material name="black"/>
    </visual>
    <inertial>
      <mass value="0.3148"/>
      <inertia ixx="7.60766666667e-05" ixy="0.0" ixz="0.0" iyy="7.60766666667e-05" iyz="0.0" izz="7.60766666667e-05"/>
    </inertial>
    <collision>
      <origin rpy="0 0 0" xyz="0 0 0"/>
      <geometry>
        <box size="0.04 0.02 0.05"/>
      </geometry>
    </collision>
  </link>
  <joint name="leftleg_ang_2_joint" type="revolute">
    <parent link="leftleg_ang_1"/>
    <child link="leftleg_ang_2"/>
    <origin xyz="-0.02 0 0"/>
    <axis xyz="0 1 0"/>
    <dynamics damping="0.7"/>
    <limit effort="20" lower="-0.785398163397" upper="0.785398163397" velocity="1.0"/>
  </joint>
  <link name="leftleg_ang_2">
    <visual>
      <origin rpy="0 0 0" xyz="0 0 -0.025"/>
      <geometry>
        <box size="0.02 0.04 0.05"/>
      </geometry>
      <material name="orange"/>
    </visual>
    <inertial>
      <mass value="0.3148"/>
      <inertia ixx="0.000107556666667" ixy="0.0" ixz="0.0" iyy="0.000107556666667" iyz="0.0" izz="0.000107556666667"/>
    </inertial>
    <collision>
      <origin rpy="0 0 0" xyz="-0.04 0 -0.025"/>
      <geometry>
        <box size="0.02 0.04 0.05"/>
      </geometry>
    </collision>
  </link>
  <joint name="leftleg_foot_joint" type="fixed">
    <parent link="leftleg_ang_2"/>
    <child link="leftleg_foot"/>
    <origin xyz="0 0 -0.05"/>
  </joint>
  <link name="leftleg_foot">
    <visual>
      <origin rpy="0 0 0" xyz="0.025 0 -0.00075"/>
      <geometry>
        <box size="0.07 0.03 0.0015"/>
      </geometry>
      <material name="orange"/>
    </visual>
    <inertial>
      <mass value="0.0247905"/>
      <inertia ixx="1.86393571875e-06" ixy="0.0" ixz="0.0" iyy="1.86393571875e-06" iyz="0.0" izz="1.86393571875e-06"/>
    </inertial>
    <collision>
      <origin rpy="0 0 0" xyz="0.025 0 -0.00075"/>
      <geometry>
        <box size="0.07 0.03 0.0015"/>
      </geometry>
    </collision>
  </link>
  <transmission name="leftleg_hip_1_tran">
    <type>transmission_interface/SimpleTransmission</type>
    <joint name="leftleg_hip_1_joint">
      <hardwareInterface>hardware_interface/EffortJointInterface</hardwareInterface>
    </joint>
    <actuator name="leftleg_hip_1_motor">
      <hardwareInterface>hardware_interface/EffortJointInterface</hardwareInterface>
      <mechanicalReduction>1</mechanicalReduction>
    </actuator>
  </transmission>
  <transmission name="leftleg_hip_2_tran">
    <type>transmission_interface/SimpleTransmission</type>
    <joint name="leftleg_hip_2_joint">
      <hardwareInterface>hardware_interface/EffortJointInterface</hardwareInterface>
    </joint>
    <actuator name="leftleg_hip_2_motor">
      <hardwareInterface>hardware_interface/EffortJointInterface</hardwareInterface>
      <mechanicalReduction>1</mechanicalReduction>
    </actuator>
  </transmission>
  <transmission name="leftleg_hip_3_tran">
    <type>transmission_interface/SimpleTransmission</type>
    <joint name="leftleg_hip_3_joint">
      <hardwareInterface>hardware_interface/EffortJointInterface</hardwareInterface>
    </joint>
    <actuator name="leftleg_hip_3_motor">
      <hardwareInterface>hardware_interface/EffortJointInterface</hardwareInterface>
      <mechanicalReduction>1</mechanicalReduction>
    </actuator>
  </transmission>
  <transmission name="leftleg_knee_tran">
    <type>transmission_interface/SimpleTransmission</type>
    <joint name="leftleg_knee_joint">
      <hardwareInterface>hardware_interface/EffortJointInterface</hardwareInterface>
    </joint>
    <actuator name="leftleg_knee_motor">
      <hardwareInterface>hardware_interface/EffortJointInterface</hardwareInterface>
      <mechanicalReduction>1</mechanicalReduction>
    </actuator>
  </transmission>
  <transmission name="leftleg_ang_1_tran">
    <type>transmission_interface/SimpleTransmission</type>
    <joint name="leftleg_ang_1_joint">
      <hardwareInterface>hardware_interface/EffortJointInterface</hardwareInterface>
    </joint>
    <actuator name="leftleg_ang_1_motor">
      <hardwareInterface>hardware_interface/EffortJointInterface</hardwareInterface>
      <mechanicalReduction>1</mechanicalReduction>
    </actuator>
  </transmission>
  <transmission name="leftleg_ang_2_tran">
    <type>transmission_interface/SimpleTransmission</type>
    <joint name="leftleg_ang_2_joint">
      <hardwareInterface>hardware_interface/EffortJointInterface</hardwareInterface>
    </joint>
    <actuator name="leftleg_ang_2_motor">
      <hardwareInterface>hardware_interface/EffortJointInterface</hardwareInterface>
      <mechanicalReduction>1</mechanicalReduction>
    </actuator>
  </transmission>
  <joint name="rightleg_hip_1_joint" type="revolute">
    <parent link="base"/>
    <child link="rightleg_hip_2"/>
    <origin xyz="0 -0.03 0"/>
    <axis xyz="0 1 0"/>
    <dynamics damping="0.7"/>
    <limit effort="20" lower="-1.57079632679" upper="1.57079632679" velocity="1.0"/>
  </joint>
  <link name="rightleg_hip_2">
    <visual>
      <origin rpy="0 0 0" xyz="0 -0.015 0"/>
      <geometry>
        <box size="0.04 0.03 0.05"/>
      </geometry>
      <material name="black"/>
    </visual>
    <inertial>
      <mass value="0.4722"/>
      <inertia ixx="0.00013379" ixy="0.0" ixz="0.0" iyy="0.00013379" iyz="0.0" izz="0.00013379"/>
    </inertial>
    <collision>
      <origin rpy="0 0 0" xyz="0 -0.015 0"/>
      <geometry>
        <box size="0.04 0.03 0.05"/>
      </geometry>
    </collision>
  </link>
  <joint name="rightleg_hip_2_joint" type="revolute">
    <parent link="rightleg_hip_2"/>
    <child link="rightleg_hip_3"/>
    <origin xyz="0 -0.03 0"/>
    <axis xyz="1 0 0"/>
    <dynamics damping="0.7"/>
    <limit effort="20" lower="-1.57079632679" upper="1.57079632679" velocity="1.0"/>
  </joint>
  <link name="rightleg_hip_3">
    <visual>
      <origin rpy="0 0 0" xyz="0 0 -0.015"/>
      <geometry>
        <box size="0.05 0.025 0.08"/>
      </geometry>
      <material name="orange"/>
    </visual>
    <inertial>
      <mass value="0.787"/>
      <inertia ixx="0.000460722916667" ixy="0.0" ixz="0.0" iyy="0.000460722916667" iyz="0.0" izz="0.000460722916667"/>
    </inertial>
    <collision>
      <origin rpy="0 0 0" xyz="0 0 -0.015"/>
      <geometry>
        <box size="0.05 0.025 0.08"/>
      </geometry>
    </collision>
  </link>
  <joint name="rightleg_hip_3_joint" type="revolute">
    <parent link="rightleg_hip_3"/>
    <child link="rightleg_upp"/>
    <origin xyz="0 0 -0.055"/>
    <axis xyz="0 0 1"/>
    <dynamics damping="0.7"/>
    <limit effort="20" lower="-1.57079632679" upper="1.57079632679" velocity="1.0"/>
  </joint>
  <link name="rightleg_upp">
    <visual>
      <origin rpy="0 0 0" xyz="0 0 -0.03"/>
      <geometry>
        <box size="0.025 0.05 0.06"/>
      </geometry>
      <material name="black"/>
    </visual>
    <inertial>
      <mass value="0.59025"/>
      <inertia ixx="0.00030004375" ixy="0.0" ixz="0.0" iyy="0.00030004375" iyz="0.0" izz="0.00030004375"/>
    </inertial>
    <collision>
      <origin rpy="0 0 0" xyz="0 0 -0.03"/>
      <geometry>
        <box size="0.025 0.05 0.06"/>
      </geometry>
    </collision>
  </link>
  <joint name="rightleg_knee_joint" type="revolute">
    <parent link="rightleg_upp"/>
    <child link="rightleg_low"/>
    <origin xyz="0 0 -0.06"/>
    <axis xyz="0 1 0"/>
    <dynamics damping="0.7"/>
    <limit effort="20" lower="0" upper="2.74889357189" velocity="1.0"/>
  </joint>
  <link name="rightleg_low">
    <visual>
      <origin rpy="0 0 0" xyz="0 0 -0.055"/>
      <geometry>
        <box size="0.01 0.01 0.11"/>
      </geometry>
      <material name="orange"/>
    </visual>
    <inertial>
      <mass value="0.08657"/>
      <inertia ixx="8.80128333333e-05" ixy="0.0" ixz="0.0" iyy="8.80128333333e-05" iyz="0.0" izz="8.80128333333e-05"/>
    </inertial>
    <collision>
      <origin rpy="0 0 0" xyz="0 0 -0.055"/>
      <geometry>
        <box size="0.01 0.01 0.11"/>
      </geometry>
    </collision>
  </link>
  <joint name="rightleg_ang_1_joint" type="revolute">
    <parent link="rightleg_low"/>
    <child link="rightleg_ang_1"/>
    <origin rpy="0 0 0" xyz="0 0 -0.085"/>
    <axis xyz="1 0 0"/>
    <dynamics damping="0.7"/>
    <limit effort="20" lower="-0.785398163397" upper="0.785398163397" velocity="1.0"/>
  </joint>
  <link name="rightleg_ang_1">
    <visual>
      <origin rpy="0 0 0" xyz="0 0 0"/>
      <geometry>
        <box size="0.04 0.02 0.05"/>
      </geometry>
      <material name="black"/>
    </visual>
    <inertial>
      <mass value="0.3148"/>
      <inertia ixx="7.60766666667e-05" ixy="0.0" ixz="0.0" iyy="7.60766666667e-05" iyz="0.0" izz="7.60766666667e-05"/>
    </inertial>
    <collision>
      <origin rpy="0 0 0" xyz="0 0 0"/>
      <geometry>
        <box size="0.04 0.02 0.05"/>
      </geometry>
    </collision>
  </link>
  <joint name="rightleg_ang_2_joint" type="revolute">
    <parent link="rightleg_ang_1"/>
    <child link="rightleg_ang_2"/>
    <origin xyz="-0.02 0 0"/>
    <axis xyz="0 1 0"/>
    <dynamics damping="0.7"/>
    <limit effort="20" lower="-0.785398163397" upper="0.785398163397" velocity="1.0"/>
  </joint>
  <link name="rightleg_ang_2">
    <visual>
      <origin rpy="0 0 0" xyz="0 0 -0.025"/>
      <geometry>
        <box size="0.02 0.04 0.05"/>
      </geometry>
      <material name="orange"/>
    </visual>
    <inertial>
      <mass value="0.3148"/>
      <inertia ixx="0.000107556666667" ixy="0.0" ixz="0.0" iyy="0.000107556666667" iyz="0.0" izz="0.000107556666667"/>
    </inertial>
    <collision>
      <origin rpy="0 0 0" xyz="-0.04 0 -0.025"/>
      <geometry>
        <box size="0.02 0.04 0.05"/>
      </geometry>
    </collision>
  </link>
  <joint name="rightleg_foot_joint" type="fixed">
    <parent link="rightleg_ang_2"/>
    <child link="rightleg_foot"/>
    <origin xyz="0 0 -0.05"/>
  </joint>
  <link name="rightleg_foot">
    <visual>
      <origin rpy="0 0 0" xyz="0.025 0 -0.00075"/>
      <geometry>
        <box size="0.07 0.03 0.0015"/>
      </geometry>
      <material name="orange"/>
    </visual>
    <inertial>
      <mass value="0.0247905"/>
      <inertia ixx="1.86393571875e-06" ixy="0.0" ixz="0.0" iyy="1.86393571875e-06" iyz="0.0" izz="1.86393571875e-06"/>
    </inertial>
    <collision>
      <origin rpy="0 0 0" xyz="0.025 0 -0.00075"/>
      <geometry>
        <box size="0.07 0.03 0.0015"/>
      </geometry>
    </collision>
  </link>
  <transmission name="rightleg_hip_1_tran">
    <type>transmission_interface/SimpleTransmission</type>
    <joint name="rightleg_hip_1_joint">
      <hardwareInterface>hardware_interface/EffortJointInterface</hardwareInterface>
    </joint>
    <actuator name="rightleg_hip_1_motor">
      <hardwareInterface>hardware_interface/EffortJointInterface</hardwareInterface>
      <mechanicalReduction>1</mechanicalReduction>
    </actuator>
  </transmission>
  <transmission name="rightleg_hip_2_tran">
    <type>transmission_interface/SimpleTransmission</type>
    <joint name="rightleg_hip_2_joint">
      <hardwareInterface>hardware_interface/EffortJointInterface</hardwareInterface>
    </joint>
    <actuator name="rightleg_hip_2_motor">
      <hardwareInterface>hardware_interface/EffortJointInterface</hardwareInterface>
      <mechanicalReduction>1</mechanicalReduction>
    </actuator>
  </transmission>
  <transmission name="rightleg_hip_3_tran">
    <type>transmission_interface/SimpleTransmission</type>
    <joint name="rightleg_hip_3_joint">
      <hardwareInterface>hardware_interface/EffortJointInterface</hardwareInterface>
    </joint>
    <actuator name="rightleg_hip_3_motor">
      <hardwareInterface>hardware_interface/EffortJointInterface</hardwareInterface>
      <mechanicalReduction>1</mechanicalReduction>
    </actuator>
  </transmission>
  <transmission name="rightleg_knee_tran">
    <type>transmission_interface/SimpleTransmission</type>
    <joint name="rightleg_knee_joint">
      <hardwareInterface>hardware_interface/EffortJointInterface</hardwareInterface>
    </joint>
    <actuator name="rightleg_knee_motor">
      <hardwareInterface>hardware_interface/EffortJointInterface</hardwareInterface>
      <mechanicalReduction>1</mechanicalReduction>
    </actuator>
  </transmission>
  <transmission name="rightleg_ang_1_tran">
    <type>transmission_interface/SimpleTransmission</type>
    <joint name="rightleg_ang_1_joint">
      <hardwareInterface>hardware_interface/EffortJointInterface</hardwareInterface>
    </joint>
    <actuator name="rightleg_ang_1_motor">
      <hardwareInterface>hardware_interface/EffortJointInterface</hardwareInterface>
      <mechanicalReduction>1</mechanicalReduction>
    </actuator>
  </transmission>
  <transmission name="rightleg_ang_2_tran">
    <type>transmission_interface/SimpleTransmission</type>
    <joint name="rightleg_ang_2_joint">
      <hardwareInterface>hardware_interface/EffortJointInterface</hardwareInterface>
    </joint>
    <actuator name="rightleg_ang_2_motor">
      <hardwareInterface>hardware_interface/EffortJointInterface</hardwareInterface>
      <mechanicalReduction>1</mechanicalReduction>
    </actuator>
  </transmission>
</robot>

