<?xml version="1.0" ?>
<!-- =================================================================================== -->
<!-- |    This document was autogenerated by xacro from robotv1.xacro                  | -->
<!-- |    EDITING THIS FILE BY HAND IS NOT RECOMMENDED                                 | -->
<!-- =================================================================================== -->
<robot name="robotv1" xmlns:xacro="http://www.ros.org/wiki/xacro">
  <material name="black">
    <color rgba="0.0 0.0 0.0 1.0"/>
  </material>
  <material name="blue">
    <color rgba="0.0 0.0 0.8 1.0"/>
  </material>
  <material name="green">
    <color rgba="0.0 0.8 0.0 1.0"/>
  </material>
  <material name="grey">
    <color rgba="0.2 0.2 0.2 1.0"/>
  </material>
  <material name="orange">
    <color rgba="1.0 0.423529411765 0.0392156862745 1.0"/>
  </material>
  <material name="brown">
    <color rgba="0.870588235294 0.811764705882 0.764705882353 1.0"/>
  </material>
  <material name="red">
    <color rgba="0.8 0.0 0.0 1.0"/>
  </material>
  <material name="white">
    <color rgba="1.0 1.0 1.0 1.0"/>
  </material>
  <gazebo>
    <plugin filename="libgazebo_ros_control.so" name="gazebo_ros_control">
      <robotNamespace>/robotv1</robotNamespace>
      <robotSimType>gazebo_ros_control/DefaultRobotHWSim</robotSimType>
      <legacyModeNS>true</legacyModeNS>
    </plugin>
  </gazebo>
  <gazebo reference="pelvis">
    <mu1>0.2</mu1>
    <mu2>0.2</mu2>
    <minDepth>0.03</minDepth>
    <self_collide>0</self_collide>
    <material>Gazebo/White</material>
  </gazebo>
  <gazebo reference="imu_link">
    <mu1>0.2</mu1>
    <mu2>0.2</mu2>
    <minDepth>0.0001</minDepth>
    <material>Gazebo/Blue</material>
    <gravity>true</gravity>
    <sensor name="imu_sensor" type="imu">
      <always_on>true</always_on>
      <update_rate>100</update_rate>
      <visualize>true</visualize>
      <topic>__default_topic__</topic>
      <plugin filename="libgazebo_ros_imu_sensor.so" name="imu_plugin">
        <topicName>imu/pelvis</topicName>
        <bodyName>imu_link_pelvis</bodyName>
        <updateRateHZ>10.0</updateRateHZ>
        <gaussianNoise>0.0</gaussianNoise>
        <xyzOffset>0 0 0</xyzOffset>
        <rpyOffset>0 0 0</rpyOffset>
        <frameName>imu_link_pelvis</frameName>
      </plugin>
      <pose>0 0 0 0 0 0</pose>
    </sensor>
  </gazebo>
  <link name="wolrd"/>
  <joint name="wolrd_to_pelvis" type="fixed">
    <origin rpy="0 0 0" xyz="0 0 0.55"/>
    <parent link="wolrd"/>
    <child link="pelvis"/>
  </joint>
  <link name="pelvis">
    <visual>
      <origin rpy="0 0 0" xyz="0 0 0"/>
      <geometry>
        <box size="0.05 0.1 0.04"/>
      </geometry>
      <material name="white"/>
    </visual>
    <inertial>
      <origin rpy="0 0 0" xyz="0 0 0"/>
      <mass value="0.4"/>
      <inertia ixx="0.000386666666667" ixy="0.0" ixz="0.0" iyy="0.000136666666667" iyz="0.0" izz="0.000416666666667"/>
    </inertial>
    <collision>
      <origin rpy="0 0 0" xyz="0 0 0"/>
      <geometry>
        <box size="0.05 0.1 0.04"/>
      </geometry>
    </collision>
  </link>
  <joint name="pelvis_to_imu_link" type="fixed">
    <origin rpy="0 0 0" xyz="0 0 -0.02"/>
    <parent link="pelvis"/>
    <child link="imu_link"/>
  </joint>
  <link name="imu_link">
    <visual>
      <origin rpy="0 0 0" xyz="0 0 -0.0025"/>
      <geometry>
        <box size="0.03 0.03 0.005"/>
      </geometry>
      <material name="blue"/>
    </visual>
    <inertial>
      <origin rpy="0 0 0" xyz="0 0 0.0025"/>
      <mass value="0.009"/>
      <inertia ixx="6.9375e-07" ixy="0.0" ixz="0.0" iyy="6.9375e-07" iyz="0.0" izz="1.35e-06"/>
    </inertial>
    <collision>
      <origin rpy="0 0 0" xyz="0 0 0"/>
      <geometry>
        <box size="0.03 0.03 0.005"/>
      </geometry>
    </collision>
  </link>
  <joint name="LLEG_H0" type="revolute">
    <parent link="pelvis"/>
    <child link="LLEG_u0"/>
    <origin xyz="0 0.05 0"/>
    <axis xyz="0 1 0"/>
    <dynamics damping="3" friction="0.025"/>
    <limit effort="30.0" lower="-1.57079632679" upper="1.57079632679" velocity="6.28318530718"/>
    <!--
      <safety_controller k_velocity="10" k_position="15" soft_lower_limit="${-7*pi/8}" soft_upper_limit="${7*pi/8}" />
       -->
  </joint>
  <transmission name="LLEG_H0_tran">
    <type>transmission_interface/SimpleTransmission</type>
    <joint name="LLEG_H0">
      <hardwareInterface>hardware_interface/EffortJointInterface</hardwareInterface>
    </joint>
    <actuator name="LLEG_H0_motor">
      <hardwareInterface>hardware_interface/EffortJointInterface</hardwareInterface>
      <mechanicalReduction>1</mechanicalReduction>
    </actuator>
  </transmission>
  <link name="LLEG_u0">
    <visual>
      <origin rpy="0 0 0" xyz="0 0.015 0"/>
      <geometry>
        <box size="0.04 0.03 0.06"/>
      </geometry>
      <material name="black"/>
    </visual>
    <inertial>
      <origin rpy="0 0 0" xyz="0 0.015 0"/>
      <mass value="0.144"/>
      <inertia ixx="5.4e-05" ixy="0.0" ixz="0.0" iyy="6.24e-05" iyz="0.0" izz="3e-05"/>
    </inertial>
    <collision>
      <origin rpy="0 0 0" xyz="0 0.015 0"/>
      <geometry>
        <box size="0.04 0.03 0.06"/>
      </geometry>
    </collision>
  </link>
  <joint name="LLEG_H1" type="revolute">
    <parent link="LLEG_u0"/>
    <child link="LLEG_u1"/>
    <origin xyz="0 0.03 0"/>
    <axis xyz="1 0 0"/>
    <dynamics damping="3" friction="0.025"/>
    <limit effort="30.0" lower="-1.57079632679" upper="1.57079632679" velocity="6.28318530718"/>
  </joint>
  <transmission name="LLEG_H1_tran">
    <type>transmission_interface/SimpleTransmission</type>
    <joint name="LLEG_H1">
      <hardwareInterface>hardware_interface/EffortJointInterface</hardwareInterface>
    </joint>
    <actuator name="LLEG_H1_motor">
      <hardwareInterface>hardware_interface/EffortJointInterface</hardwareInterface>
      <mechanicalReduction>1</mechanicalReduction>
    </actuator>
  </transmission>
  <link name="LLEG_u1">
    <visual>
      <origin rpy="0 0 0" xyz="0 0 -0.045"/>
      <geometry>
        <box size="0.06 0.03 0.09"/>
      </geometry>
      <material name="orange"/>
    </visual>
    <inertial>
      <origin rpy="0 0 0" xyz="0 0 -0.045"/>
      <mass value="0.324"/>
      <inertia ixx="0.000243" ixy="0.0" ixz="0.0" iyy="0.0003159" iyz="0.0" izz="0.0001215"/>
    </inertial>
    <collision>
      <origin rpy="0 0 0" xyz="0 0 -0.045"/>
      <geometry>
        <box size="0.06 0.03 0.09"/>
      </geometry>
    </collision>
  </link>
  <joint name="LLEG_H2" type="revolute">
    <parent link="LLEG_u1"/>
    <child link="LLEG_u2"/>
    <origin xyz="0 0 -0.09"/>
    <axis xyz="0 0 1"/>
    <dynamics damping="3" friction="0.025"/>
    <limit effort="30.0" lower="-1.57079632679" upper="1.57079632679" velocity="6.28318530718"/>
  </joint>
  <transmission name="LLEG_H2_tran">
    <type>transmission_interface/SimpleTransmission</type>
    <joint name="LLEG_H2">
      <hardwareInterface>hardware_interface/EffortJointInterface</hardwareInterface>
    </joint>
    <actuator name="LLEG_H2_motor">
      <hardwareInterface>hardware_interface/EffortJointInterface</hardwareInterface>
      <mechanicalReduction>1</mechanicalReduction>
    </actuator>
  </transmission>
  <link name="LLEG_u2">
    <visual>
      <origin rpy="0 0 0" xyz="0 0 -0.03"/>
      <geometry>
        <box size="0.03 0.04 0.06"/>
      </geometry>
      <material name="black"/>
    </visual>
    <inertial>
      <origin rpy="0 0 0" xyz="0 0 -0.03"/>
      <mass value="0.144"/>
      <inertia ixx="6.24e-05" ixy="0.0" ixz="0.0" iyy="5.4e-05" iyz="0.0" izz="3e-05"/>
    </inertial>
    <collision>
      <origin rpy="0 0 0" xyz="0 0 -0.03"/>
      <geometry>
        <box size="0.03 0.04 0.06"/>
      </geometry>
    </collision>
  </link>
  <joint name="LLEG_K0" type="revolute">
    <parent link="LLEG_u2"/>
    <child link="LLEG_l0"/>
    <origin xyz="0 0 -0.06"/>
    <axis xyz="0 1 0"/>
    <dynamics damping="3" friction="0.025"/>
    <limit effort="30.0" lower="0" upper="2.74889357189" velocity="6.28318530718"/>
  </joint>
  <transmission name="LLEG_K0_tran">
    <type>transmission_interface/SimpleTransmission</type>
    <joint name="LLEG_K0">
      <hardwareInterface>hardware_interface/EffortJointInterface</hardwareInterface>
    </joint>
    <actuator name="LLEG_K0_motor">
      <hardwareInterface>hardware_interface/EffortJointInterface</hardwareInterface>
      <mechanicalReduction>1</mechanicalReduction>
    </actuator>
  </transmission>
  <link name="LLEG_l0">
    <visual>
      <origin rpy="0 0 0" xyz="0 0 -0.08"/>
      <geometry>
        <box size="0.015 0.015 0.16"/>
      </geometry>
      <material name="orange"/>
    </visual>
    <inertial>
      <origin rpy="0 0 0" xyz="0 0 -0.08"/>
      <mass value="0.072"/>
      <inertia ixx="0.00015495" ixy="0.0" ixz="0.0" iyy="0.00015495" iyz="0.0" izz="2.7e-06"/>
    </inertial>
    <collision>
      <origin rpy="0 0 0" xyz="0 0 -0.08"/>
      <geometry>
        <box size="0.015 0.015 0.16"/>
      </geometry>
    </collision>
  </link>
  <joint name="LLEG_A0" type="revolute">
    <parent link="LLEG_l0"/>
    <child link="LLEG_l1"/>
    <origin rpy="0 0 0" xyz="0 0 -0.13"/>
    <axis xyz="1 0 0"/>
    <dynamics damping="3" friction="0.025"/>
    <limit effort="30.0" lower="-0.785398163397" upper="0.785398163397" velocity="6.28318530718"/>
  </joint>
  <transmission name="LLEG_A0_tran">
    <type>transmission_interface/SimpleTransmission</type>
    <joint name="LLEG_A0">
      <hardwareInterface>hardware_interface/EffortJointInterface</hardwareInterface>
    </joint>
    <actuator name="LLEG_A0_motor">
      <hardwareInterface>hardware_interface/EffortJointInterface</hardwareInterface>
      <mechanicalReduction>1</mechanicalReduction>
    </actuator>
  </transmission>
  <link name="LLEG_l1">
    <visual>
      <origin rpy="0 0 0" xyz="0 0 0"/>
      <geometry>
        <box size="0.04 0.03 0.06"/>
      </geometry>
      <material name="black"/>
    </visual>
    <inertial>
      <origin rpy="0 0 0" xyz="0 0 0"/>
      <mass value="0.144"/>
      <inertia ixx="5.4e-05" ixy="0.0" ixz="0.0" iyy="6.24e-05" iyz="0.0" izz="3e-05"/>
    </inertial>
    <collision>
      <origin rpy="0 0 0" xyz="0 0 0"/>
      <geometry>
        <box size="0.04 0.03 0.06"/>
      </geometry>
    </collision>
  </link>
  <joint name="LLEG_A1" type="revolute">
    <parent link="LLEG_l1"/>
    <child link="LLEG_l2"/>
    <origin xyz="-0.02 0 0"/>
    <axis xyz="0 1 0"/>
    <dynamics damping="3" friction="0.025"/>
    <limit effort="30.0" lower="-0.785398163397" upper="0.785398163397" velocity="6.28318530718"/>
  </joint>
  <transmission name="LLEG_A1_tran">
    <type>transmission_interface/SimpleTransmission</type>
    <joint name="LLEG_A1">
      <hardwareInterface>hardware_interface/EffortJointInterface</hardwareInterface>
    </joint>
    <actuator name="LLEG_A1_motor">
      <hardwareInterface>hardware_interface/EffortJointInterface</hardwareInterface>
      <mechanicalReduction>1</mechanicalReduction>
    </actuator>
  </transmission>
  <link name="LLEG_l2">
    <visual>
      <origin rpy="0 0 0" xyz="0 0 -0.03"/>
      <geometry>
        <box size="0.03 0.04 0.06"/>
      </geometry>
      <material name="orange"/>
    </visual>
    <inertial>
      <origin rpy="0 0 0" xyz="0 0 -0.03"/>
      <mass value="0.144"/>
      <inertia ixx="6.24e-05" ixy="0.0" ixz="0.0" iyy="5.4e-05" iyz="0.0" izz="3e-05"/>
    </inertial>
    <collision>
      <origin rpy="0 0 0" xyz="0 0 -0.03"/>
      <geometry>
        <box size="0.03 0.04 0.06"/>
      </geometry>
    </collision>
  </link>
  <joint name="LLEG_l3_fix" type="fixed">
    <parent link="LLEG_l2"/>
    <child link="LLEG_l3"/>
    <origin xyz="0 0 -0.06"/>
  </joint>
  <link name="LLEG_l3">
    <visual>
      <origin rpy="0 0 0" xyz="0.035 0 -0.005"/>
      <geometry>
        <box size="0.1 0.04 0.01"/>
      </geometry>
      <material name="orange"/>
    </visual>
    <inertial>
      <origin rpy="0 0 0" xyz="0.035 0 -0.005"/>
      <mass value="0.08"/>
      <inertia ixx="1.13333333333e-05" ixy="0.0" ixz="0.0" iyy="6.73333333333e-05" iyz="0.0" izz="7.73333333333e-05"/>
    </inertial>
    <collision>
      <origin rpy="0 0 0" xyz="0.035 0 -0.005"/>
      <geometry>
        <box size="0.1 0.04 0.01"/>
      </geometry>
    </collision>
  </link>
  <joint name="LLEG_l3_to_imu_link" type="fixed">
    <origin rpy="0 0 0" xyz="0.05 0 0"/>
    <parent link="LLEG_l3"/>
    <child link="LLEG_imu_link"/>
  </joint>
  <link name="LLEG_imu_link">
    <visual>
      <origin rpy="0 0 0" xyz="0 0 0.0025"/>
      <geometry>
        <box size="0.03 0.03 0.005"/>
      </geometry>
      <material name="blue"/>
    </visual>
    <inertial>
      <origin rpy="0 0 0" xyz="0 0 0.0025"/>
      <mass value="0.009"/>
      <inertia ixx="6.9375e-07" ixy="0.0" ixz="0.0" iyy="6.9375e-07" iyz="0.0" izz="1.35e-06"/>
    </inertial>
    <collision>
      <origin rpy="0 0 0" xyz="0 0 0"/>
      <geometry>
        <box size="0.03 0.03 0.005"/>
      </geometry>
    </collision>
  </link>
  <!-- Link1 -->
  <gazebo reference="LLEG_H0">
    <stopCfm>0.0</stopCfm>
    <stopErp>0.2</stopErp>
    <implicitSpringDamper>1</implicitSpringDamper>
  </gazebo>
  <gazebo reference="LLEG_u0">
    <mu1>0.2</mu1>
    <mu2>0.2</mu2>
    <dampingFactor>0.001</dampingFactor>
    <minDepth>0.003</minDepth>
    <material>Gazebo/Black</material>
  </gazebo>
  <gazebo reference="LLEG_H1">
    <stopCfm>0.0</stopCfm>
    <stopErp>0.2</stopErp>
    <implicitSpringDamper>1</implicitSpringDamper>
  </gazebo>
  <gazebo reference="LLEG_u1">
    <mu1>0.2</mu1>
    <mu2>0.2</mu2>
    <dampingFactor>0.001</dampingFactor>
    <minDepth>0.003</minDepth>
    <material>Gazebo/Orange</material>
  </gazebo>
  <gazebo reference="LLEG_H2">
    <stopCfm>0.0</stopCfm>
    <stopErp>0.2</stopErp>
    <implicitSpringDamper>1</implicitSpringDamper>
  </gazebo>
  <gazebo reference="LLEG_u2">
    <mu1>0.2</mu1>
    <mu2>0.2</mu2>
    <dampingFactor>0.001</dampingFactor>
    <minDepth>0.003</minDepth>
    <material>Gazebo/Black</material>
  </gazebo>
  <gazebo reference="LLEG_K0">
    <stopCfm>0.0</stopCfm>
    <stopErp>0.2</stopErp>
    <implicitSpringDamper>1</implicitSpringDamper>
  </gazebo>
  <gazebo reference="LLEG_l0">
    <mu1>0.2</mu1>
    <mu2>0.2</mu2>
    <dampingFactor>0.001</dampingFactor>
    <minDepth>0.003</minDepth>
    <material>Gazebo/Orange</material>
  </gazebo>
  <gazebo reference="LLEG_A0">
    <stopCfm>0.0</stopCfm>
    <stopErp>0.2</stopErp>
    <implicitSpringDamper>1</implicitSpringDamper>
  </gazebo>
  <gazebo reference="LLEG_l1">
    <mu1>0.2</mu1>
    <mu2>0.2</mu2>
    <dampingFactor>0.001</dampingFactor>
    <minDepth>0.003</minDepth>
    <material>Gazebo/Black</material>
  </gazebo>
  <gazebo reference="LLEG_A1">
    <stopCfm>0.0</stopCfm>
    <stopErp>0.2</stopErp>
    <implicitSpringDamper>1</implicitSpringDamper>
  </gazebo>
  <gazebo reference="LLEG_l2">
    <mu1>0.2</mu1>
    <mu2>0.2</mu2>
    <dampingFactor>0.001</dampingFactor>
    <minDepth>0.003</minDepth>
    <material>Gazebo/Orange</material>
  </gazebo>
  <gazebo reference="LLEG_l3">
    <mu1>0.4</mu1>
    <mu2>0.4</mu2>
    <dampingFactor>0.001</dampingFactor>
    <minDepth>0.003</minDepth>
    <material>Gazebo/Orange</material>
  </gazebo>
  <gazebo reference="LLEG_imu_link">
    <mu1>0.2</mu1>
    <mu2>0.2</mu2>
    <minDepth>0.0001</minDepth>
    <material>Gazebo/Blue</material>
    <gravity>true</gravity>
    <sensor name="imu_sensor" type="imu">
      <always_on>true</always_on>
      <update_rate>100</update_rate>
      <visualize>true</visualize>
      <topic>__default_topic__</topic>
      <plugin filename="libgazebo_ros_imu_sensor.so" name="imu_plugin">
        <topicName>imu/LLEG_l3_imu</topicName>
        <bodyName>LLEG_imu_link</bodyName>
        <updateRateHZ>10.0</updateRateHZ>
        <gaussianNoise>0.0</gaussianNoise>
        <xyzOffset>0 0 0</xyzOffset>
        <rpyOffset>0 0 0</rpyOffset>
        <frameName>LLEG_imu_link</frameName>
      </plugin>
      <pose>0 0 0 0 0 0</pose>
    </sensor>
  </gazebo>
  <joint name="RLEG_H0" type="revolute">
    <parent link="pelvis"/>
    <child link="RLEG_u0"/>
    <origin xyz="0 -0.05 0"/>
    <axis xyz="0 1 0"/>
    <dynamics damping="3" friction="0.025"/>
    <limit effort="30.0" lower="-1.57079632679" upper="1.57079632679" velocity="6.28318530718"/>
    <!--
      <safety_controller k_velocity="10" k_position="15" soft_lower_limit="${-7*pi/8}" soft_upper_limit="${7*pi/8}" />
       -->
  </joint>
  <transmission name="RLEG_H0_tran">
    <type>transmission_interface/SimpleTransmission</type>
    <joint name="RLEG_H0">
      <hardwareInterface>hardware_interface/EffortJointInterface</hardwareInterface>
    </joint>
    <actuator name="RLEG_H0_motor">
      <hardwareInterface>hardware_interface/EffortJointInterface</hardwareInterface>
      <mechanicalReduction>1</mechanicalReduction>
    </actuator>
  </transmission>
  <link name="RLEG_u0">
    <visual>
      <origin rpy="0 0 0" xyz="0 -0.015 0"/>
      <geometry>
        <box size="0.04 0.03 0.06"/>
      </geometry>
      <material name="black"/>
    </visual>
    <inertial>
      <origin rpy="0 0 0" xyz="0 -0.015 0"/>
      <mass value="0.144"/>
      <inertia ixx="5.4e-05" ixy="0.0" ixz="0.0" iyy="6.24e-05" iyz="0.0" izz="3e-05"/>
    </inertial>
    <collision>
      <origin rpy="0 0 0" xyz="0 -0.015 0"/>
      <geometry>
        <box size="0.04 0.03 0.06"/>
      </geometry>
    </collision>
  </link>
  <joint name="RLEG_H1" type="revolute">
    <parent link="RLEG_u0"/>
    <child link="RLEG_u1"/>
    <origin xyz="0 -0.03 0"/>
    <axis xyz="1 0 0"/>
    <dynamics damping="3" friction="0.025"/>
    <limit effort="30.0" lower="-1.57079632679" upper="1.57079632679" velocity="6.28318530718"/>
  </joint>
  <transmission name="RLEG_H1_tran">
    <type>transmission_interface/SimpleTransmission</type>
    <joint name="RLEG_H1">
      <hardwareInterface>hardware_interface/EffortJointInterface</hardwareInterface>
    </joint>
    <actuator name="RLEG_H1_motor">
      <hardwareInterface>hardware_interface/EffortJointInterface</hardwareInterface>
      <mechanicalReduction>1</mechanicalReduction>
    </actuator>
  </transmission>
  <link name="RLEG_u1">
    <visual>
      <origin rpy="0 0 0" xyz="0 0 -0.045"/>
      <geometry>
        <box size="0.06 0.03 0.09"/>
      </geometry>
      <material name="orange"/>
    </visual>
    <inertial>
      <origin rpy="0 0 0" xyz="0 0 -0.045"/>
      <mass value="0.324"/>
      <inertia ixx="0.000243" ixy="0.0" ixz="0.0" iyy="0.0003159" iyz="0.0" izz="0.0001215"/>
    </inertial>
    <collision>
      <origin rpy="0 0 0" xyz="0 0 -0.045"/>
      <geometry>
        <box size="0.06 0.03 0.09"/>
      </geometry>
    </collision>
  </link>
  <joint name="RLEG_H2" type="revolute">
    <parent link="RLEG_u1"/>
    <child link="RLEG_u2"/>
    <origin xyz="0 0 -0.09"/>
    <axis xyz="0 0 1"/>
    <dynamics damping="3" friction="0.025"/>
    <limit effort="30.0" lower="-1.57079632679" upper="1.57079632679" velocity="6.28318530718"/>
  </joint>
  <transmission name="RLEG_H2_tran">
    <type>transmission_interface/SimpleTransmission</type>
    <joint name="RLEG_H2">
      <hardwareInterface>hardware_interface/EffortJointInterface</hardwareInterface>
    </joint>
    <actuator name="RLEG_H2_motor">
      <hardwareInterface>hardware_interface/EffortJointInterface</hardwareInterface>
      <mechanicalReduction>1</mechanicalReduction>
    </actuator>
  </transmission>
  <link name="RLEG_u2">
    <visual>
      <origin rpy="0 0 0" xyz="0 0 -0.03"/>
      <geometry>
        <box size="0.03 0.04 0.06"/>
      </geometry>
      <material name="black"/>
    </visual>
    <inertial>
      <origin rpy="0 0 0" xyz="0 0 -0.03"/>
      <mass value="0.144"/>
      <inertia ixx="6.24e-05" ixy="0.0" ixz="0.0" iyy="5.4e-05" iyz="0.0" izz="3e-05"/>
    </inertial>
    <collision>
      <origin rpy="0 0 0" xyz="0 0 -0.03"/>
      <geometry>
        <box size="0.03 0.04 0.06"/>
      </geometry>
    </collision>
  </link>
  <joint name="RLEG_K0" type="revolute">
    <parent link="RLEG_u2"/>
    <child link="RLEG_l0"/>
    <origin xyz="0 0 -0.06"/>
    <axis xyz="0 1 0"/>
    <dynamics damping="3" friction="0.025"/>
    <limit effort="30.0" lower="0" upper="2.74889357189" velocity="6.28318530718"/>
  </joint>
  <transmission name="RLEG_K0_tran">
    <type>transmission_interface/SimpleTransmission</type>
    <joint name="RLEG_K0">
      <hardwareInterface>hardware_interface/EffortJointInterface</hardwareInterface>
    </joint>
    <actuator name="RLEG_K0_motor">
      <hardwareInterface>hardware_interface/EffortJointInterface</hardwareInterface>
      <mechanicalReduction>1</mechanicalReduction>
    </actuator>
  </transmission>
  <link name="RLEG_l0">
    <visual>
      <origin rpy="0 0 0" xyz="0 0 -0.08"/>
      <geometry>
        <box size="0.015 0.015 0.16"/>
      </geometry>
      <material name="orange"/>
    </visual>
    <inertial>
      <origin rpy="0 0 0" xyz="0 0 -0.08"/>
      <mass value="0.072"/>
      <inertia ixx="0.00015495" ixy="0.0" ixz="0.0" iyy="0.00015495" iyz="0.0" izz="2.7e-06"/>
    </inertial>
    <collision>
      <origin rpy="0 0 0" xyz="0 0 -0.08"/>
      <geometry>
        <box size="0.015 0.015 0.16"/>
      </geometry>
    </collision>
  </link>
  <joint name="RLEG_A0" type="revolute">
    <parent link="RLEG_l0"/>
    <child link="RLEG_l1"/>
    <origin rpy="0 0 0" xyz="0 0 -0.13"/>
    <axis xyz="1 0 0"/>
    <dynamics damping="3" friction="0.025"/>
    <limit effort="30.0" lower="-0.785398163397" upper="0.785398163397" velocity="6.28318530718"/>
  </joint>
  <transmission name="RLEG_A0_tran">
    <type>transmission_interface/SimpleTransmission</type>
    <joint name="RLEG_A0">
      <hardwareInterface>hardware_interface/EffortJointInterface</hardwareInterface>
    </joint>
    <actuator name="RLEG_A0_motor">
      <hardwareInterface>hardware_interface/EffortJointInterface</hardwareInterface>
      <mechanicalReduction>1</mechanicalReduction>
    </actuator>
  </transmission>
  <link name="RLEG_l1">
    <visual>
      <origin rpy="0 0 0" xyz="0 0 0"/>
      <geometry>
        <box size="0.04 0.03 0.06"/>
      </geometry>
      <material name="black"/>
    </visual>
    <inertial>
      <origin rpy="0 0 0" xyz="0 0 0"/>
      <mass value="0.144"/>
      <inertia ixx="5.4e-05" ixy="0.0" ixz="0.0" iyy="6.24e-05" iyz="0.0" izz="3e-05"/>
    </inertial>
    <collision>
      <origin rpy="0 0 0" xyz="0 0 0"/>
      <geometry>
        <box size="0.04 0.03 0.06"/>
      </geometry>
    </collision>
  </link>
  <joint name="RLEG_A1" type="revolute">
    <parent link="RLEG_l1"/>
    <child link="RLEG_l2"/>
    <origin xyz="-0.02 0 0"/>
    <axis xyz="0 1 0"/>
    <dynamics damping="3" friction="0.025"/>
    <limit effort="30.0" lower="-0.785398163397" upper="0.785398163397" velocity="6.28318530718"/>
  </joint>
  <transmission name="RLEG_A1_tran">
    <type>transmission_interface/SimpleTransmission</type>
    <joint name="RLEG_A1">
      <hardwareInterface>hardware_interface/EffortJointInterface</hardwareInterface>
    </joint>
    <actuator name="RLEG_A1_motor">
      <hardwareInterface>hardware_interface/EffortJointInterface</hardwareInterface>
      <mechanicalReduction>1</mechanicalReduction>
    </actuator>
  </transmission>
  <link name="RLEG_l2">
    <visual>
      <origin rpy="0 0 0" xyz="0 0 -0.03"/>
      <geometry>
        <box size="0.03 0.04 0.06"/>
      </geometry>
      <material name="orange"/>
    </visual>
    <inertial>
      <origin rpy="0 0 0" xyz="0 0 -0.03"/>
      <mass value="0.144"/>
      <inertia ixx="6.24e-05" ixy="0.0" ixz="0.0" iyy="5.4e-05" iyz="0.0" izz="3e-05"/>
    </inertial>
    <collision>
      <origin rpy="0 0 0" xyz="0 0 -0.03"/>
      <geometry>
        <box size="0.03 0.04 0.06"/>
      </geometry>
    </collision>
  </link>
  <joint name="RLEG_l3_fix" type="fixed">
    <parent link="RLEG_l2"/>
    <child link="RLEG_l3"/>
    <origin xyz="0 0 -0.06"/>
  </joint>
  <link name="RLEG_l3">
    <visual>
      <origin rpy="0 0 0" xyz="0.035 0 -0.005"/>
      <geometry>
        <box size="0.1 0.04 0.01"/>
      </geometry>
      <material name="orange"/>
    </visual>
    <inertial>
      <origin rpy="0 0 0" xyz="0.035 0 -0.005"/>
      <mass value="0.08"/>
      <inertia ixx="1.13333333333e-05" ixy="0.0" ixz="0.0" iyy="6.73333333333e-05" iyz="0.0" izz="7.73333333333e-05"/>
    </inertial>
    <collision>
      <origin rpy="0 0 0" xyz="0.035 0 -0.005"/>
      <geometry>
        <box size="0.1 0.04 0.01"/>
      </geometry>
    </collision>
  </link>
  <joint name="RLEG_l3_to_imu_link" type="fixed">
    <origin rpy="0 0 0" xyz="0.05 0 0"/>
    <parent link="RLEG_l3"/>
    <child link="RLEG_imu_link"/>
  </joint>
  <link name="RLEG_imu_link">
    <visual>
      <origin rpy="0 0 0" xyz="0 0 0.0025"/>
      <geometry>
        <box size="0.03 0.03 0.005"/>
      </geometry>
      <material name="blue"/>
    </visual>
    <inertial>
      <origin rpy="0 0 0" xyz="0 0 0.0025"/>
      <mass value="0.009"/>
      <inertia ixx="6.9375e-07" ixy="0.0" ixz="0.0" iyy="6.9375e-07" iyz="0.0" izz="1.35e-06"/>
    </inertial>
    <collision>
      <origin rpy="0 0 0" xyz="0 0 0"/>
      <geometry>
        <box size="0.03 0.03 0.005"/>
      </geometry>
    </collision>
  </link>
  <!-- Link1 -->
  <gazebo reference="RLEG_H0">
    <stopCfm>0.0</stopCfm>
    <stopErp>0.2</stopErp>
    <implicitSpringDamper>1</implicitSpringDamper>
  </gazebo>
  <gazebo reference="RLEG_u0">
    <mu1>0.2</mu1>
    <mu2>0.2</mu2>
    <dampingFactor>0.001</dampingFactor>
    <minDepth>0.003</minDepth>
    <material>Gazebo/Black</material>
  </gazebo>
  <gazebo reference="RLEG_H1">
    <stopCfm>0.0</stopCfm>
    <stopErp>0.2</stopErp>
    <implicitSpringDamper>1</implicitSpringDamper>
  </gazebo>
  <gazebo reference="RLEG_u1">
    <mu1>0.2</mu1>
    <mu2>0.2</mu2>
    <dampingFactor>0.001</dampingFactor>
    <minDepth>0.003</minDepth>
    <material>Gazebo/Orange</material>
  </gazebo>
  <gazebo reference="RLEG_H2">
    <stopCfm>0.0</stopCfm>
    <stopErp>0.2</stopErp>
    <implicitSpringDamper>1</implicitSpringDamper>
  </gazebo>
  <gazebo reference="RLEG_u2">
    <mu1>0.2</mu1>
    <mu2>0.2</mu2>
    <dampingFactor>0.001</dampingFactor>
    <minDepth>0.003</minDepth>
    <material>Gazebo/Black</material>
  </gazebo>
  <gazebo reference="RLEG_K0">
    <stopCfm>0.0</stopCfm>
    <stopErp>0.2</stopErp>
    <implicitSpringDamper>1</implicitSpringDamper>
  </gazebo>
  <gazebo reference="RLEG_l0">
    <mu1>0.2</mu1>
    <mu2>0.2</mu2>
    <dampingFactor>0.001</dampingFactor>
    <minDepth>0.003</minDepth>
    <material>Gazebo/Orange</material>
  </gazebo>
  <gazebo reference="RLEG_A0">
    <stopCfm>0.0</stopCfm>
    <stopErp>0.2</stopErp>
    <implicitSpringDamper>1</implicitSpringDamper>
  </gazebo>
  <gazebo reference="RLEG_l1">
    <mu1>0.2</mu1>
    <mu2>0.2</mu2>
    <dampingFactor>0.001</dampingFactor>
    <minDepth>0.003</minDepth>
    <material>Gazebo/Black</material>
  </gazebo>
  <gazebo reference="RLEG_A1">
    <stopCfm>0.0</stopCfm>
    <stopErp>0.2</stopErp>
    <implicitSpringDamper>1</implicitSpringDamper>
  </gazebo>
  <gazebo reference="RLEG_l2">
    <mu1>0.2</mu1>
    <mu2>0.2</mu2>
    <dampingFactor>0.001</dampingFactor>
    <minDepth>0.003</minDepth>
    <material>Gazebo/Orange</material>
  </gazebo>
  <gazebo reference="RLEG_l3">
    <mu1>0.4</mu1>
    <mu2>0.4</mu2>
    <dampingFactor>0.001</dampingFactor>
    <minDepth>0.003</minDepth>
    <material>Gazebo/Orange</material>
  </gazebo>
  <gazebo reference="RLEG_imu_link">
    <mu1>0.2</mu1>
    <mu2>0.2</mu2>
    <minDepth>0.0001</minDepth>
    <material>Gazebo/Blue</material>
    <gravity>true</gravity>
    <sensor name="imu_sensor" type="imu">
      <always_on>true</always_on>
      <update_rate>100</update_rate>
      <visualize>true</visualize>
      <topic>__default_topic__</topic>
      <plugin filename="libgazebo_ros_imu_sensor.so" name="imu_plugin">
        <topicName>imu/RLEG_l3_imu</topicName>
        <bodyName>RLEG_imu_link</bodyName>
        <updateRateHZ>10.0</updateRateHZ>
        <gaussianNoise>0.0</gaussianNoise>
        <xyzOffset>0 0 0</xyzOffset>
        <rpyOffset>0 0 0</rpyOffset>
        <frameName>RLEG_imu_link</frameName>
      </plugin>
      <pose>0 0 0 0 0 0</pose>
    </sensor>
  </gazebo>
</robot>

