<?xml version="1.0" ?>
<!-- =================================================================================== -->
<!-- |    This document was autogenerated by xacro from robotv1.xacro                  | -->
<!-- |    EDITING THIS FILE BY HAND IS NOT RECOMMENDED                                 | -->
<!-- =================================================================================== -->
<robot name="robotv1" xmlns:xacro="http://www.ros.org/wiki/xacro">
  <material name="black">
    <color rgba="0.0 0.0 0.0 1.0"/>
  </material>
  <material name="blue">
    <color rgba="0.0 0.0 0.8 1.0"/>
  </material>
  <material name="green">
    <color rgba="0.0 0.8 0.0 1.0"/>
  </material>
  <material name="grey">
    <color rgba="0.2 0.2 0.2 1.0"/>
  </material>
  <material name="orange">
    <color rgba="1.0 0.423529411765 0.0392156862745 1.0"/>
  </material>
  <material name="brown">
    <color rgba="0.870588235294 0.811764705882 0.764705882353 1.0"/>
  </material>
  <material name="red">
    <color rgba="0.8 0.0 0.0 1.0"/>
  </material>
  <material name="white">
    <color rgba="1.0 1.0 1.0 1.0"/>
  </material>
  <gazebo>
    <plugin filename="libgazebo_ros_control.so" name="gazebo_ros_control">
      <robotNamespace>/robotv1</robotNamespace>
      <robotSimType>gazebo_ros_control/DefaultRobotHWSim</robotSimType>
      <legacyModeNS>true</legacyModeNS>
    </plugin>
  </gazebo>
  <gazebo reference="pelvis">
    <mu1>0.2</mu1>
    <mu2>0.2</mu2>
    <minDepth>0.03</minDepth>
    <self_collide>0</self_collide>
    <material>Gazebo/White</material>
  </gazebo>
  <gazebo reference="imu_link_pelvis">
    <mu1>0.2</mu1>
    <mu2>0.2</mu2>
    <minDepth>0.0001</minDepth>
    <material>Gazebo/Blue</material>
    <gravity>true</gravity>
    <sensor name="imu_sensor" type="imu">
      <always_on>true</always_on>
      <update_rate>100</update_rate>
      <visualize>true</visualize>
      <topic>__default_topic__</topic>
      <plugin filename="libgazebo_ros_imu_sensor.so" name="imu_plugin">
        <topicName>imu/pelvis</topicName>
        <bodyName>imu_link_pelvis</bodyName>
        <updateRateHZ>10.0</updateRateHZ>
        <gaussianNoise>0.0</gaussianNoise>
        <xyzOffset>0 0 0</xyzOffset>
        <rpyOffset>0 0 0</rpyOffset>
        <frameName>imu_link_pelvis</frameName>
      </plugin>
      <pose>0 0 0 0 0 0</pose>
    </sensor>
  </gazebo>
  <link name="dummy"/>
  <joint name="dummy_to_pelvis" type="fixed">
    <origin rpy="0 0 0" xyz="0 0 0.548"/>
    <parent link="dummy"/>
    <child link="pelvis"/>
  </joint>
  <link name="pelvis">
    <visual>
      <origin rpy="0 0 0" xyz="0 0 0"/>
      <geometry>
        <box size="0.05 0.1 0.04"/>
      </geometry>
      <material name="white"/>
    </visual>
    <inertial>
      <origin rpy="0 0 0" xyz="0 0 0"/>
      <mass value="0.34"/>
      <inertia ixx="0.000328666666667" ixy="0.0" ixz="0.0" iyy="0.000116166666667" iyz="0.0" izz="0.000354166666667"/>
    </inertial>
    <collision>
      <origin rpy="0 0 0" xyz="0 0 0"/>
      <geometry>
        <box size="0.05 0.1 0.04"/>
      </geometry>
    </collision>
  </link>
  <joint name="pelvis_to_imu_link" type="fixed">
    <origin rpy="0 0 0" xyz="0 0 -0.02"/>
    <parent link="pelvis"/>
    <child link="imu_link_pelvis"/>
  </joint>
  <link name="imu_link_pelvis">
    <visual>
      <origin rpy="0 0 0" xyz="0 0 -0.0025"/>
      <geometry>
        <box size="0.03 0.03 0.005"/>
      </geometry>
      <material name="blue"/>
    </visual>
    <inertial>
      <origin rpy="0 0 0" xyz="0 0 0.0025"/>
      <mass value="0.00765"/>
      <inertia ixx="5.896875e-07" ixy="0.0" ixz="0.0" iyy="5.896875e-07" iyz="0.0" izz="1.1475e-06"/>
    </inertial>
    <collision>
      <origin rpy="0 0 0" xyz="0 0 0"/>
      <geometry>
        <box size="0.03 0.03 0.005"/>
      </geometry>
    </collision>
  </link>
  <joint name="LLEG_H0" type="revolute">
    <parent link="pelvis"/>
    <child link="LLEG_u0"/>
    <origin xyz="0 0.05 0"/>
    <axis xyz="0 1 0"/>
    <dynamics damping="0.03" friction="0.015"/>
    <limit effort="10.0" lower="-1.57079632679" upper="1.57079632679" velocity="6.0"/>
    <!--
      <safety_controller k_velocity="10" k_position="15" soft_lower_limit="${-7*pi/8}" soft_upper_limit="${7*pi/8}" />
       -->
  </joint>
  <transmission name="LLEG_H0_tran">
    <type>transmission_interface/SimpleTransmission</type>
    <joint name="LLEG_H0">
      <hardwareInterface>hardware_interface/EffortJointInterface</hardwareInterface>
    </joint>
    <actuator name="LLEG_H0_motor">
      <hardwareInterface>hardware_interface/EffortJointInterface</hardwareInterface>
      <mechanicalReduction>1</mechanicalReduction>
    </actuator>
  </transmission>
  <link name="LLEG_u0">
    <visual>
      <origin rpy="0 0 0" xyz="0 0.015 0"/>
      <geometry>
        <box size="0.04 0.03 0.06"/>
      </geometry>
      <material name="black"/>
    </visual>
    <inertial>
      <origin rpy="0 0 0" xyz="0 0.015 0"/>
      <mass value="0.1224"/>
      <inertia ixx="4.59e-05" ixy="0.0" ixz="0.0" iyy="5.304e-05" iyz="0.0" izz="2.55e-05"/>
    </inertial>
    <collision>
      <origin rpy="0 0 0" xyz="0 0.015 0"/>
      <geometry>
        <box size="0.04 0.03 0.06"/>
      </geometry>
    </collision>
  </link>
  <joint name="LLEG_H1" type="revolute">
    <parent link="LLEG_u0"/>
    <child link="LLEG_u1"/>
    <origin xyz="0 0.03 0"/>
    <axis xyz="1 0 0"/>
    <dynamics damping="0.03" friction="0.015"/>
    <limit effort="10.0" lower="-1.57079632679" upper="1.57079632679" velocity="6.0"/>
  </joint>
  <transmission name="LLEG_H1_tran">
    <type>transmission_interface/SimpleTransmission</type>
    <joint name="LLEG_H1">
      <hardwareInterface>hardware_interface/EffortJointInterface</hardwareInterface>
    </joint>
    <actuator name="LLEG_H1_motor">
      <hardwareInterface>hardware_interface/EffortJointInterface</hardwareInterface>
      <mechanicalReduction>1</mechanicalReduction>
    </actuator>
  </transmission>
  <link name="LLEG_u1">
    <visual>
      <origin rpy="0 0 0" xyz="0 0 -0.045"/>
      <geometry>
        <box size="0.06 0.03 0.09"/>
      </geometry>
      <material name="orange"/>
    </visual>
    <inertial>
      <origin rpy="0 0 0" xyz="0 0 -0.045"/>
      <mass value="0.2754"/>
      <inertia ixx="0.00020655" ixy="0.0" ixz="0.0" iyy="0.000268515" iyz="0.0" izz="0.000103275"/>
    </inertial>
    <collision>
      <origin rpy="0 0 0" xyz="0 0 -0.045"/>
      <geometry>
        <box size="0.06 0.03 0.09"/>
      </geometry>
    </collision>
  </link>
  <joint name="LLEG_H2" type="revolute">
    <parent link="LLEG_u1"/>
    <child link="LLEG_u2"/>
    <origin xyz="0 0 -0.09"/>
    <axis xyz="0 0 1"/>
    <dynamics damping="0.03" friction="0.015"/>
    <limit effort="10.0" lower="-1.57079632679" upper="1.57079632679" velocity="6.0"/>
  </joint>
  <transmission name="LLEG_H2_tran">
    <type>transmission_interface/SimpleTransmission</type>
    <joint name="LLEG_H2">
      <hardwareInterface>hardware_interface/EffortJointInterface</hardwareInterface>
    </joint>
    <actuator name="LLEG_H2_motor">
      <hardwareInterface>hardware_interface/EffortJointInterface</hardwareInterface>
      <mechanicalReduction>1</mechanicalReduction>
    </actuator>
  </transmission>
  <link name="LLEG_u2">
    <visual>
      <origin rpy="0 0 0" xyz="0 0 -0.03"/>
      <geometry>
        <box size="0.03 0.04 0.06"/>
      </geometry>
      <material name="black"/>
    </visual>
    <inertial>
      <origin rpy="0 0 0" xyz="0 0 -0.03"/>
      <mass value="0.1224"/>
      <inertia ixx="5.304e-05" ixy="0.0" ixz="0.0" iyy="4.59e-05" iyz="0.0" izz="2.55e-05"/>
    </inertial>
    <collision>
      <origin rpy="0 0 0" xyz="0 0 -0.03"/>
      <geometry>
        <box size="0.03 0.04 0.06"/>
      </geometry>
    </collision>
  </link>
  <joint name="LLEG_K0" type="revolute">
    <parent link="LLEG_u2"/>
    <child link="LLEG_l0"/>
    <origin xyz="0 0 -0.06"/>
    <axis xyz="0 1 0"/>
    <dynamics damping="0.03" friction="0.015"/>
    <limit effort="10.0" lower="0" upper="2.74889357189" velocity="6.0"/>
  </joint>
  <transmission name="LLEG_K0_tran">
    <type>transmission_interface/SimpleTransmission</type>
    <joint name="LLEG_K0">
      <hardwareInterface>hardware_interface/EffortJointInterface</hardwareInterface>
    </joint>
    <actuator name="LLEG_K0_motor">
      <hardwareInterface>hardware_interface/EffortJointInterface</hardwareInterface>
      <mechanicalReduction>1</mechanicalReduction>
    </actuator>
  </transmission>
  <link name="LLEG_l0">
    <visual>
      <origin rpy="0 0 0" xyz="0 0 -0.08"/>
      <geometry>
        <box size="0.015 0.015 0.16"/>
      </geometry>
      <material name="orange"/>
    </visual>
    <inertial>
      <origin rpy="0 0 0" xyz="0 0 -0.08"/>
      <mass value="0.0612"/>
      <inertia ixx="0.0001317075" ixy="0.0" ixz="0.0" iyy="0.0001317075" iyz="0.0" izz="2.295e-06"/>
    </inertial>
    <collision>
      <origin rpy="0 0 0" xyz="0 0 -0.08"/>
      <geometry>
        <box size="0.015 0.015 0.16"/>
      </geometry>
    </collision>
  </link>
  <joint name="LLEG_A0" type="revolute">
    <parent link="LLEG_l0"/>
    <child link="LLEG_l1"/>
    <origin rpy="0 0 0" xyz="0 0 -0.13"/>
    <axis xyz="1 0 0"/>
    <dynamics damping="0.03" friction="0.015"/>
    <limit effort="10.0" lower="-0.785398163397" upper="0.785398163397" velocity="6.0"/>
  </joint>
  <transmission name="LLEG_A0_tran">
    <type>transmission_interface/SimpleTransmission</type>
    <joint name="LLEG_A0">
      <hardwareInterface>hardware_interface/EffortJointInterface</hardwareInterface>
    </joint>
    <actuator name="LLEG_A0_motor">
      <hardwareInterface>hardware_interface/EffortJointInterface</hardwareInterface>
      <mechanicalReduction>1</mechanicalReduction>
    </actuator>
  </transmission>
  <link name="LLEG_l1">
    <visual>
      <origin rpy="0 0 0" xyz="0 0 0"/>
      <geometry>
        <box size="0.04 0.03 0.06"/>
      </geometry>
      <material name="black"/>
    </visual>
    <inertial>
      <origin rpy="0 0 0" xyz="0 0 0"/>
      <mass value="0.1224"/>
      <inertia ixx="4.59e-05" ixy="0.0" ixz="0.0" iyy="5.304e-05" iyz="0.0" izz="2.55e-05"/>
    </inertial>
    <collision>
      <origin rpy="0 0 0" xyz="0 0 0"/>
      <geometry>
        <box size="0.04 0.03 0.06"/>
      </geometry>
    </collision>
  </link>
  <joint name="LLEG_A1" type="revolute">
    <parent link="LLEG_l1"/>
    <child link="LLEG_l2"/>
    <origin xyz="-0.02 0 0"/>
    <axis xyz="0 1 0"/>
    <dynamics damping="0.03" friction="0.015"/>
    <limit effort="10.0" lower="-0.785398163397" upper="0.785398163397" velocity="6.0"/>
  </joint>
  <transmission name="LLEG_A1_tran">
    <type>transmission_interface/SimpleTransmission</type>
    <joint name="LLEG_A1">
      <hardwareInterface>hardware_interface/EffortJointInterface</hardwareInterface>
    </joint>
    <actuator name="LLEG_A1_motor">
      <hardwareInterface>hardware_interface/EffortJointInterface</hardwareInterface>
      <mechanicalReduction>1</mechanicalReduction>
    </actuator>
  </transmission>
  <link name="LLEG_l2">
    <visual>
      <origin rpy="0 0 0" xyz="0 0 -0.03"/>
      <geometry>
        <box size="0.03 0.04 0.06"/>
      </geometry>
      <material name="orange"/>
    </visual>
    <inertial>
      <origin rpy="0 0 0" xyz="0 0 -0.03"/>
      <mass value="0.1224"/>
      <inertia ixx="5.304e-05" ixy="0.0" ixz="0.0" iyy="4.59e-05" iyz="0.0" izz="2.55e-05"/>
    </inertial>
    <collision>
      <origin rpy="0 0 0" xyz="0 0 -0.03"/>
      <geometry>
        <box size="0.03 0.04 0.06"/>
      </geometry>
    </collision>
  </link>
  <joint name="LLEG_l3_fix" type="fixed">
    <parent link="LLEG_l2"/>
    <child link="LLEG_l3"/>
    <origin xyz="0 0 -0.06"/>
  </joint>
  <link name="LLEG_l3">
    <visual>
      <origin rpy="0 0 0" xyz="0.035 0 -0.004"/>
      <geometry>
        <box size="0.1 0.04 0.008"/>
      </geometry>
      <material name="orange"/>
    </visual>
    <inertial>
      <origin rpy="0 0 0" xyz="0.035 0 -0.004"/>
      <mass value="0.0544"/>
      <inertia ixx="7.54346666667e-06" ixy="0.0" ixz="0.0" iyy="4.56234666667e-05" iyz="0.0" izz="5.25866666667e-05"/>
    </inertial>
    <collision>
      <origin rpy="0 0 0" xyz="0.035 0 -0.004"/>
      <geometry>
        <box size="0.1 0.04 0.008"/>
      </geometry>
    </collision>
  </link>
  <joint name="LLEG_ft_sensor" type="fixed">
    <parent link="LLEG_l3"/>
    <child link="LLEG_l4"/>
    <origin xyz="0.035 0 -0.008"/>
    <!--   <limit upper="0" lower="0" effort="0" velocity="1"/>
      <dynamics damping="0.0" friction="0.0"/>
  -->
  </joint>
  <link name="LLEG_l4">
    <visual>
      <origin rpy="0 0 0" xyz="0 0 -0.0025"/>
      <geometry>
        <box size="0.1 0.04 0.005"/>
      </geometry>
      <material name="black"/>
    </visual>
    <inertial>
      <origin rpy="0 0 0" xyz="0 0 -0.0025"/>
      <mass value="0.034"/>
      <inertia ixx="4.60416666667e-06" ixy="0.0" ixz="0.0" iyy="2.84041666667e-05" iyz="0.0" izz="3.28666666667e-05"/>
    </inertial>
    <collision>
      <origin rpy="0 0 0" xyz="0 0 -0.0025"/>
      <geometry>
        <box size="0.1 0.04 0.005"/>
      </geometry>
    </collision>
  </link>
  <joint name="LLEG_l3_to_imu_link" type="fixed">
    <origin rpy="0 0 0" xyz="0.05 0 0"/>
    <parent link="LLEG_l3"/>
    <child link="LLEG_imu_link"/>
  </joint>
  <link name="LLEG_imu_link">
    <visual>
      <origin rpy="0 0 0" xyz="0 0 0.0025"/>
      <geometry>
        <box size="0.03 0.03 0.005"/>
      </geometry>
      <material name="blue"/>
    </visual>
    <inertial>
      <origin rpy="0 0 0" xyz="0 0 0.0025"/>
      <mass value="0.00765"/>
      <inertia ixx="5.896875e-07" ixy="0.0" ixz="0.0" iyy="5.896875e-07" iyz="0.0" izz="1.1475e-06"/>
    </inertial>
    <collision>
      <origin rpy="0 0 0" xyz="0 0 0"/>
      <geometry>
        <box size="0.03 0.03 0.005"/>
      </geometry>
    </collision>
  </link>
  <!-- Link1 -->
  <gazebo reference="LLEG_H0">
    <stopCfm>0.0</stopCfm>
    <stopErp>0.2</stopErp>
    <implicitSpringDamper>1</implicitSpringDamper>
    <provideFeedback>1</provideFeedback>
  </gazebo>
  <gazebo reference="LLEG_u0">
    <mu1>0.2</mu1>
    <mu2>0.2</mu2>
    <dampingFactor>0.01</dampingFactor>
    <minDepth>0.003</minDepth>
    <material>Gazebo/Black</material>
  </gazebo>
  <gazebo reference="LLEG_H1">
    <stopCfm>0.0</stopCfm>
    <stopErp>0.2</stopErp>
    <implicitSpringDamper>1</implicitSpringDamper>
    <provideFeedback>1</provideFeedback>
  </gazebo>
  <gazebo reference="LLEG_u1">
    <mu1>0.2</mu1>
    <mu2>0.2</mu2>
    <dampingFactor>0.01</dampingFactor>
    <minDepth>0.003</minDepth>
    <material>Gazebo/Orange</material>
  </gazebo>
  <gazebo reference="LLEG_H2">
    <stopCfm>0.0</stopCfm>
    <stopErp>0.2</stopErp>
    <implicitSpringDamper>1</implicitSpringDamper>
    <provideFeedback>1</provideFeedback>
  </gazebo>
  <gazebo reference="LLEG_u2">
    <mu1>0.2</mu1>
    <mu2>0.2</mu2>
    <dampingFactor>0.01</dampingFactor>
    <minDepth>0.003</minDepth>
    <material>Gazebo/Black</material>
  </gazebo>
  <gazebo reference="LLEG_K0">
    <stopCfm>0.0</stopCfm>
    <stopErp>0.2</stopErp>
    <implicitSpringDamper>1</implicitSpringDamper>
    <provideFeedback>1</provideFeedback>
  </gazebo>
  <gazebo reference="LLEG_l0">
    <mu1>0.2</mu1>
    <mu2>0.2</mu2>
    <dampingFactor>0.01</dampingFactor>
    <minDepth>0.003</minDepth>
    <material>Gazebo/Orange</material>
  </gazebo>
  <gazebo reference="LLEG_A0">
    <stopCfm>0.0</stopCfm>
    <stopErp>0.2</stopErp>
    <implicitSpringDamper>1</implicitSpringDamper>
    <provideFeedback>1</provideFeedback>
  </gazebo>
  <gazebo reference="LLEG_l1">
    <mu1>0.2</mu1>
    <mu2>0.2</mu2>
    <dampingFactor>0.01</dampingFactor>
    <minDepth>0.003</minDepth>
    <material>Gazebo/Black</material>
  </gazebo>
  <gazebo reference="LLEG_A1">
    <stopCfm>0.0</stopCfm>
    <stopErp>0.2</stopErp>
    <implicitSpringDamper>1</implicitSpringDamper>
    <provideFeedback>1</provideFeedback>
  </gazebo>
  <gazebo reference="LLEG_l2">
    <mu1>0.2</mu1>
    <mu2>0.2</mu2>
    <dampingFactor>0.01</dampingFactor>
    <minDepth>0.003</minDepth>
    <material>Gazebo/Orange</material>
  </gazebo>
  <gazebo reference="LLEG_l3">
    <mu1>0.4</mu1>
    <mu2>0.4</mu2>
    <dampingFactor>0.01</dampingFactor>
    <minDepth>0.003</minDepth>
    <material>Gazebo/Orange</material>
  </gazebo>
  <gazebo reference="LLEG_l4">
    <mu1>1</mu1>
    <mu2>1</mu2>
    <dampingFactor>0.01</dampingFactor>
    <minDepth>0.001</minDepth>
    <material>Gazebo/Black</material>
  </gazebo>
  <gazebo reference="LLEG_ft_sensor">
    <provideFeedback>true</provideFeedback>
    <!--    <plugin name="${prefix}_ft_sensor" filename="libgazebo_ros_ft_sensor.so">
        <updateRate>100.0</updateRate>
        <topicName>${prefix}_ft_sensor_data</topicName> 
        <jointName>${prefix}_ft_sensor</jointName>
        <noise>
          <type>gaussian</type>
          <mean>0.0</mean>
          <stddev>0.003</stddev>  
        </noise>
      </plugin>
-->
    <sensor name="LLEG_ft_sensor" type="force_torque">
      <update_rate>30</update_rate>
    </sensor>
  </gazebo>
  <gazebo reference="LLEG_imu_link">
    <mu1>0.2</mu1>
    <mu2>0.2</mu2>
    <minDepth>0.0001</minDepth>
    <material>Gazebo/Blue</material>
    <gravity>true</gravity>
    <sensor name="imu_sensor" type="imu">
      <always_on>true</always_on>
      <update_rate>100</update_rate>
      <visualize>true</visualize>
      <topic>__default_topic__</topic>
      <plugin filename="libgazebo_ros_imu_sensor.so" name="imu_plugin">
        <topicName>imu/LLEG_l3_imu</topicName>
        <bodyName>LLEG_imu_link</bodyName>
        <updateRateHZ>10.0</updateRateHZ>
        <gaussianNoise>0.0</gaussianNoise>
        <xyzOffset>0 0 0</xyzOffset>
        <rpyOffset>0 0 0</rpyOffset>
        <frameName>LLEG_imu_link</frameName>
      </plugin>
      <pose>0 0 0 0 0 0</pose>
    </sensor>
  </gazebo>
  <joint name="RLEG_H0" type="revolute">
    <parent link="pelvis"/>
    <child link="RLEG_u0"/>
    <origin xyz="0 -0.05 0"/>
    <axis xyz="0 1 0"/>
    <dynamics damping="0.03" friction="0.015"/>
    <limit effort="10.0" lower="-1.57079632679" upper="1.57079632679" velocity="6.0"/>
    <!--
      <safety_controller k_velocity="10" k_position="15" soft_lower_limit="${-7*pi/8}" soft_upper_limit="${7*pi/8}" />
       -->
  </joint>
  <transmission name="RLEG_H0_tran">
    <type>transmission_interface/SimpleTransmission</type>
    <joint name="RLEG_H0">
      <hardwareInterface>hardware_interface/EffortJointInterface</hardwareInterface>
    </joint>
    <actuator name="RLEG_H0_motor">
      <hardwareInterface>hardware_interface/EffortJointInterface</hardwareInterface>
      <mechanicalReduction>1</mechanicalReduction>
    </actuator>
  </transmission>
  <link name="RLEG_u0">
    <visual>
      <origin rpy="0 0 0" xyz="0 -0.015 0"/>
      <geometry>
        <box size="0.04 0.03 0.06"/>
      </geometry>
      <material name="black"/>
    </visual>
    <inertial>
      <origin rpy="0 0 0" xyz="0 -0.015 0"/>
      <mass value="0.1224"/>
      <inertia ixx="4.59e-05" ixy="0.0" ixz="0.0" iyy="5.304e-05" iyz="0.0" izz="2.55e-05"/>
    </inertial>
    <collision>
      <origin rpy="0 0 0" xyz="0 -0.015 0"/>
      <geometry>
        <box size="0.04 0.03 0.06"/>
      </geometry>
    </collision>
  </link>
  <joint name="RLEG_H1" type="revolute">
    <parent link="RLEG_u0"/>
    <child link="RLEG_u1"/>
    <origin xyz="0 -0.03 0"/>
    <axis xyz="1 0 0"/>
    <dynamics damping="0.03" friction="0.015"/>
    <limit effort="10.0" lower="-1.57079632679" upper="1.57079632679" velocity="6.0"/>
  </joint>
  <transmission name="RLEG_H1_tran">
    <type>transmission_interface/SimpleTransmission</type>
    <joint name="RLEG_H1">
      <hardwareInterface>hardware_interface/EffortJointInterface</hardwareInterface>
    </joint>
    <actuator name="RLEG_H1_motor">
      <hardwareInterface>hardware_interface/EffortJointInterface</hardwareInterface>
      <mechanicalReduction>1</mechanicalReduction>
    </actuator>
  </transmission>
  <link name="RLEG_u1">
    <visual>
      <origin rpy="0 0 0" xyz="0 0 -0.045"/>
      <geometry>
        <box size="0.06 0.03 0.09"/>
      </geometry>
      <material name="orange"/>
    </visual>
    <inertial>
      <origin rpy="0 0 0" xyz="0 0 -0.045"/>
      <mass value="0.2754"/>
      <inertia ixx="0.00020655" ixy="0.0" ixz="0.0" iyy="0.000268515" iyz="0.0" izz="0.000103275"/>
    </inertial>
    <collision>
      <origin rpy="0 0 0" xyz="0 0 -0.045"/>
      <geometry>
        <box size="0.06 0.03 0.09"/>
      </geometry>
    </collision>
  </link>
  <joint name="RLEG_H2" type="revolute">
    <parent link="RLEG_u1"/>
    <child link="RLEG_u2"/>
    <origin xyz="0 0 -0.09"/>
    <axis xyz="0 0 1"/>
    <dynamics damping="0.03" friction="0.015"/>
    <limit effort="10.0" lower="-1.57079632679" upper="1.57079632679" velocity="6.0"/>
  </joint>
  <transmission name="RLEG_H2_tran">
    <type>transmission_interface/SimpleTransmission</type>
    <joint name="RLEG_H2">
      <hardwareInterface>hardware_interface/EffortJointInterface</hardwareInterface>
    </joint>
    <actuator name="RLEG_H2_motor">
      <hardwareInterface>hardware_interface/EffortJointInterface</hardwareInterface>
      <mechanicalReduction>1</mechanicalReduction>
    </actuator>
  </transmission>
  <link name="RLEG_u2">
    <visual>
      <origin rpy="0 0 0" xyz="0 0 -0.03"/>
      <geometry>
        <box size="0.03 0.04 0.06"/>
      </geometry>
      <material name="black"/>
    </visual>
    <inertial>
      <origin rpy="0 0 0" xyz="0 0 -0.03"/>
      <mass value="0.1224"/>
      <inertia ixx="5.304e-05" ixy="0.0" ixz="0.0" iyy="4.59e-05" iyz="0.0" izz="2.55e-05"/>
    </inertial>
    <collision>
      <origin rpy="0 0 0" xyz="0 0 -0.03"/>
      <geometry>
        <box size="0.03 0.04 0.06"/>
      </geometry>
    </collision>
  </link>
  <joint name="RLEG_K0" type="revolute">
    <parent link="RLEG_u2"/>
    <child link="RLEG_l0"/>
    <origin xyz="0 0 -0.06"/>
    <axis xyz="0 1 0"/>
    <dynamics damping="0.03" friction="0.015"/>
    <limit effort="10.0" lower="0" upper="2.74889357189" velocity="6.0"/>
  </joint>
  <transmission name="RLEG_K0_tran">
    <type>transmission_interface/SimpleTransmission</type>
    <joint name="RLEG_K0">
      <hardwareInterface>hardware_interface/EffortJointInterface</hardwareInterface>
    </joint>
    <actuator name="RLEG_K0_motor">
      <hardwareInterface>hardware_interface/EffortJointInterface</hardwareInterface>
      <mechanicalReduction>1</mechanicalReduction>
    </actuator>
  </transmission>
  <link name="RLEG_l0">
    <visual>
      <origin rpy="0 0 0" xyz="0 0 -0.08"/>
      <geometry>
        <box size="0.015 0.015 0.16"/>
      </geometry>
      <material name="orange"/>
    </visual>
    <inertial>
      <origin rpy="0 0 0" xyz="0 0 -0.08"/>
      <mass value="0.0612"/>
      <inertia ixx="0.0001317075" ixy="0.0" ixz="0.0" iyy="0.0001317075" iyz="0.0" izz="2.295e-06"/>
    </inertial>
    <collision>
      <origin rpy="0 0 0" xyz="0 0 -0.08"/>
      <geometry>
        <box size="0.015 0.015 0.16"/>
      </geometry>
    </collision>
  </link>
  <joint name="RLEG_A0" type="revolute">
    <parent link="RLEG_l0"/>
    <child link="RLEG_l1"/>
    <origin rpy="0 0 0" xyz="0 0 -0.13"/>
    <axis xyz="1 0 0"/>
    <dynamics damping="0.03" friction="0.015"/>
    <limit effort="10.0" lower="-0.785398163397" upper="0.785398163397" velocity="6.0"/>
  </joint>
  <transmission name="RLEG_A0_tran">
    <type>transmission_interface/SimpleTransmission</type>
    <joint name="RLEG_A0">
      <hardwareInterface>hardware_interface/EffortJointInterface</hardwareInterface>
    </joint>
    <actuator name="RLEG_A0_motor">
      <hardwareInterface>hardware_interface/EffortJointInterface</hardwareInterface>
      <mechanicalReduction>1</mechanicalReduction>
    </actuator>
  </transmission>
  <link name="RLEG_l1">
    <visual>
      <origin rpy="0 0 0" xyz="0 0 0"/>
      <geometry>
        <box size="0.04 0.03 0.06"/>
      </geometry>
      <material name="black"/>
    </visual>
    <inertial>
      <origin rpy="0 0 0" xyz="0 0 0"/>
      <mass value="0.1224"/>
      <inertia ixx="4.59e-05" ixy="0.0" ixz="0.0" iyy="5.304e-05" iyz="0.0" izz="2.55e-05"/>
    </inertial>
    <collision>
      <origin rpy="0 0 0" xyz="0 0 0"/>
      <geometry>
        <box size="0.04 0.03 0.06"/>
      </geometry>
    </collision>
  </link>
  <joint name="RLEG_A1" type="revolute">
    <parent link="RLEG_l1"/>
    <child link="RLEG_l2"/>
    <origin xyz="-0.02 0 0"/>
    <axis xyz="0 1 0"/>
    <dynamics damping="0.03" friction="0.015"/>
    <limit effort="10.0" lower="-0.785398163397" upper="0.785398163397" velocity="6.0"/>
  </joint>
  <transmission name="RLEG_A1_tran">
    <type>transmission_interface/SimpleTransmission</type>
    <joint name="RLEG_A1">
      <hardwareInterface>hardware_interface/EffortJointInterface</hardwareInterface>
    </joint>
    <actuator name="RLEG_A1_motor">
      <hardwareInterface>hardware_interface/EffortJointInterface</hardwareInterface>
      <mechanicalReduction>1</mechanicalReduction>
    </actuator>
  </transmission>
  <link name="RLEG_l2">
    <visual>
      <origin rpy="0 0 0" xyz="0 0 -0.03"/>
      <geometry>
        <box size="0.03 0.04 0.06"/>
      </geometry>
      <material name="orange"/>
    </visual>
    <inertial>
      <origin rpy="0 0 0" xyz="0 0 -0.03"/>
      <mass value="0.1224"/>
      <inertia ixx="5.304e-05" ixy="0.0" ixz="0.0" iyy="4.59e-05" iyz="0.0" izz="2.55e-05"/>
    </inertial>
    <collision>
      <origin rpy="0 0 0" xyz="0 0 -0.03"/>
      <geometry>
        <box size="0.03 0.04 0.06"/>
      </geometry>
    </collision>
  </link>
  <joint name="RLEG_l3_fix" type="fixed">
    <parent link="RLEG_l2"/>
    <child link="RLEG_l3"/>
    <origin xyz="0 0 -0.06"/>
  </joint>
  <link name="RLEG_l3">
    <visual>
      <origin rpy="0 0 0" xyz="0.035 0 -0.004"/>
      <geometry>
        <box size="0.1 0.04 0.008"/>
      </geometry>
      <material name="orange"/>
    </visual>
    <inertial>
      <origin rpy="0 0 0" xyz="0.035 0 -0.004"/>
      <mass value="0.0544"/>
      <inertia ixx="7.54346666667e-06" ixy="0.0" ixz="0.0" iyy="4.56234666667e-05" iyz="0.0" izz="5.25866666667e-05"/>
    </inertial>
    <collision>
      <origin rpy="0 0 0" xyz="0.035 0 -0.004"/>
      <geometry>
        <box size="0.1 0.04 0.008"/>
      </geometry>
    </collision>
  </link>
  <joint name="RLEG_ft_sensor" type="fixed">
    <parent link="RLEG_l3"/>
    <child link="RLEG_l4"/>
    <origin xyz="0.035 0 -0.008"/>
    <!--   <limit upper="0" lower="0" effort="0" velocity="1"/>
      <dynamics damping="0.0" friction="0.0"/>
  -->
  </joint>
  <link name="RLEG_l4">
    <visual>
      <origin rpy="0 0 0" xyz="0 0 -0.0025"/>
      <geometry>
        <box size="0.1 0.04 0.005"/>
      </geometry>
      <material name="black"/>
    </visual>
    <inertial>
      <origin rpy="0 0 0" xyz="0 0 -0.0025"/>
      <mass value="0.034"/>
      <inertia ixx="4.60416666667e-06" ixy="0.0" ixz="0.0" iyy="2.84041666667e-05" iyz="0.0" izz="3.28666666667e-05"/>
    </inertial>
    <collision>
      <origin rpy="0 0 0" xyz="0 0 -0.0025"/>
      <geometry>
        <box size="0.1 0.04 0.005"/>
      </geometry>
    </collision>
  </link>
  <joint name="RLEG_l3_to_imu_link" type="fixed">
    <origin rpy="0 0 0" xyz="0.05 0 0"/>
    <parent link="RLEG_l3"/>
    <child link="RLEG_imu_link"/>
  </joint>
  <link name="RLEG_imu_link">
    <visual>
      <origin rpy="0 0 0" xyz="0 0 0.0025"/>
      <geometry>
        <box size="0.03 0.03 0.005"/>
      </geometry>
      <material name="blue"/>
    </visual>
    <inertial>
      <origin rpy="0 0 0" xyz="0 0 0.0025"/>
      <mass value="0.00765"/>
      <inertia ixx="5.896875e-07" ixy="0.0" ixz="0.0" iyy="5.896875e-07" iyz="0.0" izz="1.1475e-06"/>
    </inertial>
    <collision>
      <origin rpy="0 0 0" xyz="0 0 0"/>
      <geometry>
        <box size="0.03 0.03 0.005"/>
      </geometry>
    </collision>
  </link>
  <!-- Link1 -->
  <gazebo reference="RLEG_H0">
    <stopCfm>0.0</stopCfm>
    <stopErp>0.2</stopErp>
    <implicitSpringDamper>1</implicitSpringDamper>
    <provideFeedback>1</provideFeedback>
  </gazebo>
  <gazebo reference="RLEG_u0">
    <mu1>0.2</mu1>
    <mu2>0.2</mu2>
    <dampingFactor>0.01</dampingFactor>
    <minDepth>0.003</minDepth>
    <material>Gazebo/Black</material>
  </gazebo>
  <gazebo reference="RLEG_H1">
    <stopCfm>0.0</stopCfm>
    <stopErp>0.2</stopErp>
    <implicitSpringDamper>1</implicitSpringDamper>
    <provideFeedback>1</provideFeedback>
  </gazebo>
  <gazebo reference="RLEG_u1">
    <mu1>0.2</mu1>
    <mu2>0.2</mu2>
    <dampingFactor>0.01</dampingFactor>
    <minDepth>0.003</minDepth>
    <material>Gazebo/Orange</material>
  </gazebo>
  <gazebo reference="RLEG_H2">
    <stopCfm>0.0</stopCfm>
    <stopErp>0.2</stopErp>
    <implicitSpringDamper>1</implicitSpringDamper>
    <provideFeedback>1</provideFeedback>
  </gazebo>
  <gazebo reference="RLEG_u2">
    <mu1>0.2</mu1>
    <mu2>0.2</mu2>
    <dampingFactor>0.01</dampingFactor>
    <minDepth>0.003</minDepth>
    <material>Gazebo/Black</material>
  </gazebo>
  <gazebo reference="RLEG_K0">
    <stopCfm>0.0</stopCfm>
    <stopErp>0.2</stopErp>
    <implicitSpringDamper>1</implicitSpringDamper>
    <provideFeedback>1</provideFeedback>
  </gazebo>
  <gazebo reference="RLEG_l0">
    <mu1>0.2</mu1>
    <mu2>0.2</mu2>
    <dampingFactor>0.01</dampingFactor>
    <minDepth>0.003</minDepth>
    <material>Gazebo/Orange</material>
  </gazebo>
  <gazebo reference="RLEG_A0">
    <stopCfm>0.0</stopCfm>
    <stopErp>0.2</stopErp>
    <implicitSpringDamper>1</implicitSpringDamper>
    <provideFeedback>1</provideFeedback>
  </gazebo>
  <gazebo reference="RLEG_l1">
    <mu1>0.2</mu1>
    <mu2>0.2</mu2>
    <dampingFactor>0.01</dampingFactor>
    <minDepth>0.003</minDepth>
    <material>Gazebo/Black</material>
  </gazebo>
  <gazebo reference="RLEG_A1">
    <stopCfm>0.0</stopCfm>
    <stopErp>0.2</stopErp>
    <implicitSpringDamper>1</implicitSpringDamper>
    <provideFeedback>1</provideFeedback>
  </gazebo>
  <gazebo reference="RLEG_l2">
    <mu1>0.2</mu1>
    <mu2>0.2</mu2>
    <dampingFactor>0.01</dampingFactor>
    <minDepth>0.003</minDepth>
    <material>Gazebo/Orange</material>
  </gazebo>
  <gazebo reference="RLEG_l3">
    <mu1>0.4</mu1>
    <mu2>0.4</mu2>
    <dampingFactor>0.01</dampingFactor>
    <minDepth>0.003</minDepth>
    <material>Gazebo/Orange</material>
  </gazebo>
  <gazebo reference="RLEG_l4">
    <mu1>1</mu1>
    <mu2>1</mu2>
    <dampingFactor>0.01</dampingFactor>
    <minDepth>0.001</minDepth>
    <material>Gazebo/Black</material>
  </gazebo>
  <gazebo reference="RLEG_ft_sensor">
    <provideFeedback>true</provideFeedback>
    <!--    <plugin name="${prefix}_ft_sensor" filename="libgazebo_ros_ft_sensor.so">
        <updateRate>100.0</updateRate>
        <topicName>${prefix}_ft_sensor_data</topicName> 
        <jointName>${prefix}_ft_sensor</jointName>
        <noise>
          <type>gaussian</type>
          <mean>0.0</mean>
          <stddev>0.003</stddev>  
        </noise>
      </plugin>
-->
    <sensor name="RLEG_ft_sensor" type="force_torque">
      <update_rate>30</update_rate>
    </sensor>
  </gazebo>
  <gazebo reference="RLEG_imu_link">
    <mu1>0.2</mu1>
    <mu2>0.2</mu2>
    <minDepth>0.0001</minDepth>
    <material>Gazebo/Blue</material>
    <gravity>true</gravity>
    <sensor name="imu_sensor" type="imu">
      <always_on>true</always_on>
      <update_rate>100</update_rate>
      <visualize>true</visualize>
      <topic>__default_topic__</topic>
      <plugin filename="libgazebo_ros_imu_sensor.so" name="imu_plugin">
        <topicName>imu/RLEG_l3_imu</topicName>
        <bodyName>RLEG_imu_link</bodyName>
        <updateRateHZ>10.0</updateRateHZ>
        <gaussianNoise>0.0</gaussianNoise>
        <xyzOffset>0 0 0</xyzOffset>
        <rpyOffset>0 0 0</rpyOffset>
        <frameName>RLEG_imu_link</frameName>
      </plugin>
      <pose>0 0 0 0 0 0</pose>
    </sensor>
  </gazebo>
</robot>

